Workbook

Sheet Table of Contents
A1: File | B1: Electronics Manufacturing Venture | E1: Red | F1: Borders
A2: Author(s) | B2: Krishnamurthy Bindumadhavan, Sri Krishna P | E2: Blue | F2: Input cells
A3: Tab | B3: Table of contents | E3: Green | F3: Cells linked to another sheet
A4: Created | B4: 46033 | E4: Black | F4: Cells containing a calculation on the same sheet
C6: Worksheets
C7: Table of Contents | E7: Input Cells | F7: Description
C8: Assumptions | E8: Yes | F8: All relevant assumptions
C9: Net Income Analysis | E9: No | F9: NI trend and related analysis
C10: Revenue Analysis | E10: No | F10: Revenue trend and related analysis
C11: Expense Analysis | E11: No | F11: Expense trend and related analysis
C12: Casflow Analysis | E12: No | F12: Cashflow trend and waterfall
C13: Income Statement | E13: No | F13: Income Statement
C14: Balance Sheet | E14: No | F14: Balance Sheet
C15: Casflow Statement | E15: No | F15: Statement of Cashflows
C16: Valuation | E16: Yes | F16: NPV and IRR calculations
C17: Loan Repayment Schedule | E17: No | F17: Loan Repayment Schedule
C18: Depreciation Schedule | E18: No | F18: Depreciation Schedule
... C20: Existing Practice Valuation | E20: Yes | F20: Valuation for purchase of existing practice
A1048543: sri rama jayam
A1048544: sri rama jayam
A1048545: sri rama jayam

Sheet Bill of materials
A1: Optimised UAV Bill of Materials — PX4 + ROS 2 + Jetson Orin Nano + Livox Mid-360
A2: Target AUW: 3.2–3.4 kg | Reliability-first | Internationally proven components | Prices in INR (June 2026)
A3: Category | B3: Recommended Component | C3: Manufacturer | D3: Model | E3: Qty | F3: Verified Unit Price (₹) | G3: Total Cost (₹) | H3: Weight (g) | I3: Source | J3: Reason | K3: Alternative Replaced
A4: Frame | B4: Tarot TL65B44 X6 CF 650mm Frame | C4: Tarot | D4: TL65B44 650mm X6 | E4: 1 | F4: 8500 | G4: 8500 | H4: 415 | I4: Banggood/AliExpress ~$95 ≈ ₹8,500 | J4: CF, proven airframe, lighter | K4: Skynexus S-1 CF 650mm (~₹16,999)
A5: Flight Controller | B5: Holybro Pixhawk 6C (FC only) | C5: Holybro | D5: Pixhawk 6C Standard Set | E5: 1 | F5: 28500 | G5: 28500 | H5: 38 | I5: holybro.com $339 ≈ ₹28,500 | J5: PX4 native, globally proven | K5: Agam Autopilot V6X-RT (~₹42,000)
A6: GPS | B6: Holybro M10-100 GPS | C6: Holybro | D6: M10-100 u-blox M10 | E6: 1 | F6: 6200 | G6: 6200 | H6: 18 | I6: holybro.com ~$74 ≈ ₹6,200 | J6: u-blox M10, CAN/UART, cheaper | K6: Agam GNSS01 CAN (~₹16,000)
A7: Telemetry | B7: Holybro SiK Telemetry Radio V3 915MHz | C7: Holybro / RFDesign | D7: SiK V3 915MHz 500mW | E7: 1 | F7: 7800 | G7: 7800 | H7: 16 | I7: holybro.com ~$88 ≈ ₹7,800 | J7: 500mW, MAVLink native, FHSS | K7: Generic SiK V3 433MHz (~₹9,566)
A8: RC System | B8: RadioMaster TX16S MkII + RP3 ELRS Rx | C8: RadioMaster | D8: TX16S MkII ELRS + RP3 | E8: 1 | F8: 18500 | G8: 18500 | H8: 952 | I8: UAVGarage India ~₹17,999+₹500 | J8: ELRS, 250Hz, globally standard | K8: Same — price verified
A9: Motors | B9: T-Motor MN3110-17 700KV ×4 | C9: T-Motor | D9: MN3110-17 700KV | E9: 4 | F9: 5200 | G9: 20800 | H9: 110 | I9: tmotor.com ~$62/pc ≈ ₹5,200 | J9: Aerospace grade, long lifespan | K9: Mechtex KV700 (~₹3,200/pc, B2B only)
A10: ESCs | B10: Holybro Kotleta20 DShot ESC ×4 | C10: Holybro | D10: Kotleta20 20A DShot600 | E10: 4 | F10: 3800 | G10: 15200 | H10: 13 | I10: holybro.com ~$45/pc ≈ ₹3,800 | J10: DShot600, PX4 native, CAN | K10: Bharath IBESC 40A (~₹2,500, B2B)
A11: Propellers | B11: T-Motor 11×3.7 CF Props (2 pairs) | C11: T-Motor | D11: T11×3.7 CF CW+CCW | E11: 2 | F11: 2900 | G11: 5800 | H11: 14 | I11: tmotor.com ~$34/pair ≈ ₹2,900 | J11: Balanced, low vibration, CF | K11: Bharath 11×4.7 CF (~₹450/pc, B2B)
A12: Battery | B12: Tattu 6S 8000mAh 25C LiPo | C12: Tattu (Gens Ace) | D12: 6S 22.2V 8000mAh 25C XT60 | E12: 1 | F12: 14716 | G12: 14716 | H12: 800 | I12: RC Mumbai ₹14,716 / UAVGarage ₹13,201 excl. tax | J12: Higher capacity, longer flight time | K12: Tattu R-Line 6S 8000mAh 95C
A13: Power Distribution | B13: Matek FCHUB-12S PDB 5V/12V BEC | C13: Matek Systems | D13: FCHUB-12S | E13: 1 | F13: 2100 | G13: 2100 | H13: 22 | I13: robu.in ~₹2,100 | J13: Public retail, integrated BEC | K13: Flameback 12S PDB (~₹4,600, B2B)
A14: Companion Computer | B14: NVIDIA Jetson Orin Nano 8GB Module | C14: NVIDIA | D14: Jetson Orin Nano 8GB SOM | E14: 1 | F14: 29650 | G14: 29650 | H14: 50 | I14: ThinkRobotics ₹29,650 (verified) | J14: Core requirement, keep as-is | K14: Same — project requirement
A15: LiDAR | B15: Livox Mid-360 3D LiDAR | C15: Livox (DJI) | D15: Mid-360 | E15: 1 | F15: 85000 | G15: 85000 | H15: 265 | I15: Hexaero India ~₹85,000 | J15: Core SLAM requirement, keep | K15: Same — project requirement
... A21: Miscellaneous | B21: Arm/Disarm Safety Switch | C21: Holybro / Generic | D21: PX4 Safety Switch | E21: 1 | F21: 350 | G21: 350 | H21: 12 | I21: robu.in ~₹350 | J21: PX4 mandatory, others removed | K21: Safety+LED+Cooling bundle (~₹2,000)
A23: 💰 TOTAL COMPONENT COST | F23: 260165 | G23: INR — components only, excl. shipping & taxes
A24: ⚖ TOTAL COMPONENT WEIGHT | F24: 3475 | G24: grams — multiplied by quantity
A25: 🕐 ESTIMATED FLIGHT TIME | F25: ~18–22 min | G25: 6S 8000mAh @ ~250W avg cruise draw
A26: 🛸 ESTIMATED TAKEOFF WEIGHT (AUW) | F26: ~3,250 g | G26: Incl. 800g battery + 265g LiDAR + structure
A27: Edge & Fog Node — Rough BOM Estimates (USD)
A28: Note: Directional estimates only, not vendor-verified like the Bill of Materials tab in the main financial model. Get 2-3 real vendor quotes before finalizing. All prices in USD. | F28: =F23/Assumptions!D32 -> 2726.5248
A30: EDGE NODE (ruggedized on-site laptop, per unit)
A31: Category | B31: Component / Spec | C31: Est. Price | D31: Note
A32: Base unit | B32: Rugged laptop base (CPU, RAM, chassis) — Dell Latitude Rugged / Panasonic Toughbook class, i7, 32GB RAM, MIL-STD-810 | C32: 2200 | D32: Base rugged shell + CPU/RAM
A33: GPU | B33: Discrete GPU upgrade (Nvidia T500 / RTX A1000-class or RTX 4060 mobile) for real-time CV inference | C33: 500 | D33: Sized for inference, not training
A34: Storage | B34: 1-2TB NVMe SSD (buffer for raw imagery before fog sync) | C34: 150
A35: Connectivity | B35: 5G/LTE module or dongle for field sites | C35: 150
A36: Enclosure | B36: Rugged carry case + vehicle/field mounts | C36: 200
A37: Power | B37: Portable battery pack / field UPS | C37: 150
A38: Peripherals | B38: Rugged mouse, cables, spare battery | C38: 150
A39: EDGE NODE TOTAL (per unit) | C39: 3500
A41: FOG NODE (one server per worksite)
A42: Category | B42: Component / Spec | C42: Est. Price | D42: Note
A43: Server base | B43: 1U/2U rackmount chassis + single Xeon/EPYC CPU, industrial-grade | C43: 2500
A44: GPU | B44: Single Nvidia RTX A4000/A5000-class (16-24GB VRAM) | C44: 2200 | D44: Sized for site-wide aggregation, not training
A45: RAM | B45: 64-128GB ECC | C45: 500
A46: Storage | B46: 4-8TB NVMe/RAID array | C46: 800 | D46: Buffer before cloud sync
A47: Power | B47: UPS / power backup | C47: 500 | D47: Important for industrial sites w/ unreliable power
A48: Networking | B48: Managed switch + site Wi-Fi access point | C48: 400 | D48: Connects edge nodes on-site
...

Sheet Assumptions
C7: No of business days | D7: =12*(30 - 8) - 10 -> 254
C8: Units per day (initial) | F8: Operating Costs
C9: Growth rate (annual) | D9: 0.06 | F9: Rent | G9: =5000*12 -> 60000 | I9: Headcount increase(annual)
C10: International sales premium | D10: 0.15 | F10: Utilities | G10: =1000*12 -> 12000 | I10: Staff growth rate | J10: 0.11
C11: Annual CPI | D11: 0.03 | F11: Telephone/ Internet | G11: =100*12 -> 1200 | I11: Engineers growth rate | J11: 0.1
C12: Tax rate | D12: 0.35 | F12: Courier/ postage | G12: =1000*12 -> 12000
C13: % of new customers also taking subscription | D13: 0.85 | F13: Marketing & Advertising | G13: =500*12 -> 6000 | I13: CPI Table | J13: Year | U13: Software subscription churn rate | V13: Rate | X13: Country | Y13: Tax rate | AB13: Operating Cost table | AC13: India | AD13: USA | AE13: Europe | AF13: Australia | AG13: Canada | AH13: South America | AI13: Mexico | AJ13: Africa | AK13: Middle East | AL13: Far East | AN13: Certain other Cost table | AO13: India | AP13: USA | AQ13: Europe | AR13: Australia | AS13: Canada | AT13: South America | AU13: Mexico | AV13: Africa | AW13: Middle East | AX13: Far East
C14: Interest Rate | D14: 0.15 | F14: Insurance | G14: =500*12 -> 6000 | J14: 1 | K14: 2 | L14: 3 | M14: 4 | N14: 5 | O14: 6 | P14: 7 | Q14: 8 | R14: 9 | S14: 10
C15: Loan Term | D15: 10 | E15: Years | F15: IT Support | G15: 1000 | I15: India | J15: 0.046 | K15: 0.046 | L15: 0.046 | M15: 0.046 | N15: 0.046 | O15: 0.046 | P15: 0.046 | Q15: 0.046 | R15: 0.046 | S15: 0.046 | U15: India | V15: 0.15 | X15: India | Y15: 0.3 | AB15: Rent | AC15: 6000 | AD15: 0 | AE15: 0 | AF15: 0 | AG15: 0 | AH15: 0 | AI15: 0 | AJ15: 0 | AK15: 0 | AL15: 0 | AN15: Achitect/Designer Fees | AO15: 5000 | AP15: 5000 | AQ15: 5000 | AR15: 5000 | AS15: 5000 | AT15: 5000 | AU15: 5000 | AV15: 5000 | AW15: 5000 | AX15: 5000
C16: Depreciable life | D16: 10 | E16: Years | F16: Legal/ Accountancy | G16: 1000 | I16: USA | J16: 0.02 | K16: 0.02 | L16: 0.02 | M16: 0.02 | N16: 0.02 | O16: 0.02 | P16: 0.02 | Q16: 0.02 | R16: 0.02 | S16: 0.02 | U16: USA | V16: 0.12 | X16: USA | Y16: 0.37 | AB16: Utilities | AC16: 12000 | AD16: 0 | AE16: 0 | AF16: 0 | AG16: 0 | AH16: 0 | AI16: 0 | AJ16: 0 | AK16: 0 | AL16: 0 | AN16: Rental Deposit (lease) | AO16: 15000 | AP16: 15000 | AQ16: 15000 | AR16: 15000 | AS16: 15000 | AT16: 15000 | AU16: 15000 | AV16: 15000 | AW16: 15000 | AX16: 15000
F17: Software Systems | G17: =500*12 -> 6000 | I17: Australia | J17: 0.04 | K17: 0.04 | L17: 0.04 | M17: 0.04 | N17: 0.04 | O17: 0.04 | P17: 0.04 | Q17: 0.04 | R17: 0.04 | S17: 0.04 | U17: Australia | V17: 0.14 | X17: Australia | Y17: 0.33 | Z17: (avg) | AB17: Telephone/ Internet | AC17: 1200 | AD17: 0 | AE17: 0 | AF17: 0 | AG17: 0 | AH17: 0 | AI17: 0 | AJ17: 0 | AK17: 0 | AL17: 0 | AN17: Utilities Deposit | AO17: 1000 | AP17: 1000 | AQ17: 1000 | AR17: 1000 | AS17: 1000 | AT17: 1000 | AU17: 1000 | AV17: 1000 | AW17: 1000 | AX17: 1000
C18: Startup Costs | F18: Salaries & Benefits cost - Staff | G18: =G28*G29*G30 -> 31200 | I18: Canada | J18: 0.032 | K18: 0.032 | L18: 0.032 | M18: 0.032 | N18: 0.032 | O18: 0.032 | P18: 0.032 | Q18: 0.032 | R18: 0.032 | S18: 0.032 | U18: Canada | V18: 0.12 | X18: Canada | Y18: 0.26 | Z18: (avg) | AB18: Courier/ postage per unit | AC18: 12 | AD18: 100 | AE18: 100 | AF18: 85 | AG18: 100 | AH18: 110 | AI18: 110 | AJ18: 75 | AK18: 45 | AL18: 45 | AN18: Marketing & Advertising (Launch) | AO18: 5000 | AP18: 5000 | AQ18: 5000 | AR18: 5000 | AS18: 5000 | AT18: 5000 | AU18: 5000 | AV18: 5000 | AW18: 5000 | AX18: 5000
C19: Equipment | D19: 120000 | F19: Salaries & Benefits cost - Engineers | G19: 120000 | I19: Europe | J19: 0.0315 | K19: 0.0315 | L19: 0.0315 | M19: 0.0315 | N19: 0.0315 | O19: 0.0315 | P19: 0.0315 | Q19: 0.0315 | R19: 0.0315 | S19: 0.0315 | U19: Europe | V19: 0.13 | X19: Europe | Y19: 0.19 | AB19: Marketing & Advertising (%) | AC19: 0.22 | AD19: 0.22 | AE19: 0.22 | AF19: 0.22 | AG19: 0.22 | AH19: 0.22 | AI19: 0.22 | AJ19: 0.22 | AK19: 0.22 | AL19: 0.22 | AN19: Legal | AO19: 1000 | AP19: 1000 | AQ19: 1000 | AR19: 1000 | AS19: 1000 | AT19: 1000 | AU19: 1000 | AV19: 1000 | AW19: 1000 | AX19: 1000
C20: Factory Fit-out | D20: 75000 | F20: Security | G20: =100*12 -> 1200 | I20: South America | J20: 0.1 | K20: 0.1 | L20: 0.1 | M20: 0.1 | N20: 0.1 | O20: 0.1 | P20: 0.1 | Q20: 0.1 | R20: 0.1 | S20: 0.1 | U20: South America | V20: 0.11 | X20: South America | Y20: 0.2838 | AB20: Insurance | AC20: 6000 | AD20: 0 | AE20: 0 | AF20: 0 | AG20: 0 | AH20: 0 | AI20: 0 | AJ20: 0 | AK20: 0 | AL20: 0 | AN20: Training | AO20: 3000 | AP20: 3000 | AQ20: 3000 | AR20: 3000 | AS20: 3000 | AT20: 3000 | AU20: 3000 | AV20: 3000 | AW20: 3000 | AX20: 3000
C21: Security Equipment | D21: 5000 | F21: Subscriptions/ Memberships | G21: 1000 | I21: Middle East | J21: 0.023 | K21: 0.023 | L21: 0.023 | M21: 0.023 | N21: 0.023 | O21: 0.023 | P21: 0.023 | Q21: 0.023 | R21: 0.023 | S21: 0.023 | U21: Middle East | V21: 0.13 | X21: Middle East | Y21: 0.15 | AB21: IT Support | AC21: 1000 | AD21: 1000 | AE21: 1000 | AF21: 1000 | AG21: 1000 | AH21: 1000 | AI21: 1000 | AJ21: 1000 | AK21: 1000 | AL21: 1000 | AN21: Miscellaneous / Contingency | AO21: 5000 | AP21: 5000 | AQ21: 5000 | AR21: 5000 | AS21: 5000 | AT21: 5000 | AU21: 5000 | AV21: 5000 | AW21: 5000 | AX21: 5000
C22: IT Installation | D22: 5000 | F22: Miscellaneous / Contingency | G22: 5000 | I22: Far East | J22: 0.021 | K22: 0.021 | L22: 0.021 | M22: 0.021 | N22: 0.021 | O22: 0.021 | P22: 0.021 | Q22: 0.021 | R22: 0.021 | S22: 0.021 | U22: Far East | V22: 0.15 | X22: Far East | Y22: 0.23 | AB22: Legal/ Accountancy | AC22: 1000 | AD22: 1000 | AE22: 1000 | AF22: 1000 | AG22: 1000 | AH22: 1000 | AI22: 1000 | AJ22: 1000 | AK22: 1000 | AL22: 1000 | AN22: Repair/ Maintenance | AO22: 5000 | AP22: 5000 | AQ22: 5000 | AR22: 5000 | AS22: 5000 | AT22: 5000 | AU22: 5000 | AV22: 5000 | AW22: 5000 | AX22: 5000
C23: Software | D23: 5000 | I23: Africa | J23: 0.05 | K23: 0.05 | L23: 0.05 | M23: 0.05 | N23: 0.05 | O23: 0.05 | P23: 0.05 | Q23: 0.05 | R23: 0.05 | S23: 0.05 | U23: Africa | V23: 0.1 | X23: Africa | Y23: 0.27 | AB23: Software Systems (base) | AC23: 600 | AD23: 600 | AE23: 6000 | AF23: 6000 | AG23: 6000 | AH23: 6000 | AI23: 6000 | AJ23: 6000 | AK23: 6000 | AL23: 6000 | AN23: Licenses / Permits | AO23: 500 | AP23: 500 | AQ23: 500 | AR23: 500 | AS23: 500 | AT23: 500 | AU23: 500 | AV23: 500 | AW23: 500 | AX23: 500
F24: Costs Occuring Once a Year | I24: Mexico | J24: 0.045 | K24: 0.045 | L24: 0.045 | M24: 0.045 | N24: 0.045 | O24: 0.045 | P24: 0.045 | Q24: 0.045 | R24: 0.045 | S24: 0.045 | U24: Mexico | V24: 0.17 | X24: Mexico | Y24: 0.3 | AB24: Cost per extra user | AC24: 5 | AD24: 5 | AE24: 5 | AF24: 5 | AG24: 5 | AH24: 5 | AI24: 5 | AJ24: 5 | AK24: 5 | AL24: 5
C25: Achitect/Designer Fees | D25: 5000 | F25: Repair/ Maintenance | G25: 5000 | AB25: Salaries & Benefits cost - Staff | AC25: 31200 | AD25: 0 | AE25: 0 | AF25: 0 | AG25: 0 | AH25: 0 | AI25: 0 | AJ25: 0 | AK25: 0 | AL25: 0
C26: Rental Deposit (Lease) | D26: =G9/12*3 -> 15000 | F26: Licenses / Permits | G26: 500 | AB26: Salaries & Benefits cost - Engineers | AC26: 120000 | AD26: 0 | AE26: 0 | AF26: 0 | AG26: 0 | AH26: 0 | AI26: 0 | AJ26: 0 | AK26: 0 | AL26: 0
C27: Utilities Deposit | D27: 1000 | F27: Days inventory outstanding | G27: 75 | AB27: Security | AC27: 1200 | AD27: 1200 | AE27: 1200 | AF27: 1200 | AG27: 1200 | AH27: 1200 | AI27: 1200 | AJ27: 1200 | AK27: 1200 | AL27: 1200
C28: Marketing & Advertising (Launch) | D28: 5000 | F28: Staff compensation per hour | G28: 15 | AB28: Subscriptions/ Memberships | AC28: 1000 | AD28: 1000 | AE28: 1000 | AF28: 1000 | AG28: 1000 | AH28: 1000 | AI28: 1000 | AJ28: 1000 | AK28: 1000 | AL28: 1000
C29: Legal | D29: 1000 | F29: Hours worked per week (per FTE) | G29: 40 | AB29: Miscellaneous / Contingency | AC29: 5000 | AD29: 5000 | AE29: 5000 | AF29: 5000 | AG29: 5000 | AH29: 5000 | AI29: 5000 | AJ29: 5000 | AK29: 5000 | AL29: 5000
C30: Training | D30: 3000 | F30: # of weeks in a year | G30: 52
C31: Miscellaneous / Contingency | D31: 5000 | F31: Days sales outstanding | G31: 50
C32: Exchange rate (Dollar to Rupee) | D32: 95.42 | F32: Days payable outstanding | G32: 55
C33: Product Type | D33: % Patients opting | E33: Cash Fee | F33: Insurance Fee | G33: % Cash | H33: % Insurance | I33: Fee per test
C34: Eye Test | D34: 1 | E34: 120 | F34: =2/3*E34 -> 80 | G34: 0.8 | H34: =1-G34 -> 0.2 | I34: =SUMPRODUCT(E34:F34,G34:H34) -> 112
C35: Diabetes | D35: 0.2 | E35: 200 | F35: =2/3*E35 -> 133.33333 | G35: 0.8 | H35: =1-G35 -> 0.2 | I35: =SUMPRODUCT(E35:F35,G35:H35) -> 186.66667
C36: Hypertension | D36: 0.2 | E36: 200 | F36: =2/3*E36 -> 133.33333 | G36: 0.8 | H36: =1-G36 -> 0.2 | I36: =SUMPRODUCT(E36:F36,G36:H36) -> 186.66667
C37: Glaucoma | D37: 0.1 | E37: 300 | F37: =2/3*E37 -> 200 | G37: 0.8 | H37: =1-G37 -> 0.2 | I37: =SUMPRODUCT(E37:F37,G37:H37) -> 280
C38: Dry Eye | D38: 0.3 | E38: 120 | F38: =2/3*E38 -> 80 | G38: 0.8 | H38: =1-G38 -> 0.2 | I38: =SUMPRODUCT(E38:F38,G38:H38) -> 112
C39: Macular Degeneration | D39: 0.05 | E39: 300 | F39: =2/3*E39 -> 200 | G39: 0.8 | H39: =1-G39 -> 0.2 | I39: =SUMPRODUCT(E39:F39,G39:H39) -> 280
F43: Selling year
C44: Product | D44: Units per Year (Yr1) | E44: Annual Growth rate | F44: India | G44: USA | H44: Europe | I44: Australia | J44: Canada | K44: South America | L44: Mexico | M44: Africa | N44: Middle East | O44: Far East | P44: Selling Price | Q44: COGS | R44: Discounts | S44: Inventory
C45: Far Edge (Drone) | D45: =1540 -> 1540 | E45: 0.15 | F45: 1 | G45: 4 | H45: 4 | I45: 4 | J45: 4 | K45: 4 | L45: 4 | M45: 4 | N45: 4 | O45: 4 | P45: 5000 | Q45: 0.35 | R45: 0 | S45: =T45 -> 269500 | T45: =Q45*P45*D45/10 -> 269500 | W45: =SUM(S45:S49) -> 933600
C46: Far edge (Rover) | D46: 1000 | E46: 0.15 | F46: 1 | G46: 4 | H46: 4 | I46: 4 | J46: 4 | K46: 4 | L46: 4 | M46: 4 | N46: 4 | O46: 4 | P46: 7000 | Q46: 0.35 | R46: 0 | S46: =T46 -> 245000 | T46: =Q46*P46*D46/10 -> 245000
C47: Edge | D47: 1270 | E47: 0.15 | F47: 1 | G47: 4 | H47: 4 | I47: 4 | J47: 4 | K47: 4 | L47: 4 | M47: 4 | N47: 4 | O47: 4 | P47: 4000 | Q47: 0.35 | R47: 0 | S47: =T47 -> 177800 | T47: =Q47*P47*D47/10 -> 177800
C48: FOG | D48: 635 | E48: 0.1 | F48: 2 | G48: 5 | H48: 5 | I48: 5 | J48: 5 | K48: 5 | L48: 5 | M48: 5 | N48: 5 | O48: 5 | P48: 9500 | Q48: 0.4 | R48: 0 | S48: =T48 -> 241300 | T48: =Q48*P48*D48/10 -> 241300
C49: Enterprise | D49: 318 | E49: 0.1 | F49: 3 | G49: 6 | H49: 6 | I49: 6 | J49: 6 | K49: 6 | L49: 6 | M49: 6 | N49: 6 | O49: 6 | P49: 10000 | Q49: 0.4 | R49: 0 | S49: =0 -> 0
...

Sheet Revenue
C1: INDIA | D1: USA | E1: AUSTRALIA | F1: CANADA | G1: EUROPE | H1: SOUTH AMERICA | I1: MEXICO | J1: AFRICA | K1: MIDDLE EAST | L1: FAR EAST
B3: CPI | C3: =Assumptions!J15 -> 0.046 | D3: =Assumptions!K15 -> 0.046 | E3: =Assumptions!L15 -> 0.046 | F3: =Assumptions!M15 -> 0.046 | G3: =Assumptions!N15 -> 0.046 | H3: =Assumptions!O15 -> 0.046 | I3: =Assumptions!P15 -> 0.046 | J3: =Assumptions!Q15 -> 0.046 | ... L3: =Assumptions!S15 -> 0.046 | AB3: CPI | AC3: =Assumptions!J17 -> 0.04 | AD3: =Assumptions!K17 -> 0.04 | AE3: =Assumptions!L17 -> 0.04 | AF3: =Assumptions!M17 -> 0.04 | AG3: =Assumptions!N17 -> 0.04 | AH3: =Assumptions!O17 -> 0.04 | AI3: =Assumptions!P17 -> 0.04 | AJ3: =Assumptions!Q17 -> 0.04 | ... AL3: =Assumptions!S17 -> 0.04
C6: Year | Q6: Year | AC6: Year | AQ6: Year
B7: SELLING PRICE | C7: 1 | D7: 2 | E7: 3 | F7: 4 | G7: 5 | H7: 6 | I7: 7 | J7: 8 | K7: 9 | L7: 10 | P7: UNITS SOLD | Q7: 1 | R7: 2 | S7: 3 | T7: 4 | U7: 5 | V7: 6 | W7: 7 | X7: 8 | Y7: 9 | Z7: 10 | AB7: SELLING PRICE | AC7: 1 | AD7: 2 | AE7: 3 | AF7: 4 | AG7: 5 | AH7: 6 | AI7: 7 | AJ7: 8 | AK7: 9 | AL7: 10 | AP7: UNITS SOLD | AQ7: 1 | AR7: 2 | AS7: 3 | AT7: 4 | AU7: 5 | AV7: 6 | AW7: 7 | AX7: 8 | AY7: 9 | AZ7: 10
B8: Drone | C8: =IF(C7=Assumptions!$F$45, Assumptions!$P$45, 0) -> 5000 | D8: =IF(D7>Assumptions!$F$45, C8*(1+C3), IF(D7=Assumptions!$F$45, Assumptions!$P$45, 0)) -> 5230 | E8: =IF(E7>Assumptions!$F$45, D8*(1+D3), IF(E7=Assumptions!$F$45, Assumptions!$P$45, 0)) -> 5470.58 | F8: =IF(F7>Assumptions!$F$45, E8*(1+E3), IF(F7=Assumptions!$F$45, Assumptions!$P$45, 0)) -> 5722.2267 | G8: =IF(G7>Assumptions!$F$45, F8*(1+F3), IF(G7=Assumptions!$F$45, Assumptions!$P$45, 0)) -> 5985.4491 | H8: =IF(H7>Assumptions!$F$45, G8*(1+G3), IF(H7=Assumptions!$F$45, Assumptions!$P$45, 0)) -> 6260.7798 | I8: =IF(I7>Assumptions!$F$45, H8*(1+H3), IF(I7=Assumptions!$F$45, Assumptions!$P$45, 0)) -> 6548.7756 | J8: =IF(J7>Assumptions!$F$45, I8*(1+I3), IF(J7=Assumptions!$F$45, Assumptions!$P$45, 0)) -> 6850.0193 | K8: =IF(K7>Assumptions!$F$45, J8*(1+J3), IF(K7=Assumptions!$F$45, Assumptions!$P$45, 0)) -> 7165.1202 | L8: =IF(L7>Assumptions!$F$45, K8*(1+K3), IF(L7=Assumptions!$F$45, Assumptions!$P$45, 0)) -> 7494.7157 | P8: Drone | Q8: =IF(Q7=Assumptions!$F$45, Assumptions!$D$45, 0) -> 1540 | R8: =IF(R7>Assumptions!$F$45, Q8*(1+C22), IF(R7=Assumptions!$F$45, Assumptions!$D$45, 0)) -> 1617 | S8: =IF(S7>Assumptions!$F$45, R8*(1+D22), IF(S7=Assumptions!$F$45, Assumptions!$D$45, 0)) -> 1702.0654 | T8: =IF(T7>Assumptions!$F$45, S8*(1+E22), IF(T7=Assumptions!$F$45, Assumptions!$D$45, 0)) -> 1797.0459 | U8: =IF(U7>Assumptions!$F$45, T8*(1+F22), IF(U7=Assumptions!$F$45, Assumptions!$D$45, 0)) -> 1902.2922 | V8: =IF(V7>Assumptions!$F$45, U8*(1+G22), IF(V7=Assumptions!$F$45, Assumptions!$D$45, 0)) -> 2018.623 | W8: =IF(W7>Assumptions!$F$45, V8*(1+H22), IF(W7=Assumptions!$F$45, Assumptions!$D$45, 0)) -> 2150.0655 | X8: =IF(X7>Assumptions!$F$45, W8*(1+I22), IF(X7=Assumptions!$F$45, Assumptions!$D$45, 0)) -> 2297.7602 | Y8: =IF(Y7>Assumptions!$F$45, X8*(1+J22), IF(Y7=Assumptions!$F$45, Assumptions!$D$45, 0)) -> 2464.5299 | Z8: =IF(Z7>Assumptions!$F$45, Y8*(1+K22), IF(Z7=Assumptions!$F$45, Assumptions!$D$45, 0)) -> 2653.2324 | AB8: Drone | AC8: =IF(AC$67=Assumptions!$I$45, Assumptions!$P$45, 0) -> 0 | AD8: =IF(AD7>Assumptions!$I$45, AC8*(1+AC3), IF(AD7=Assumptions!$I$45, Assumptions!$P$45, 0)) -> 0 | AE8: =IF(AE7>Assumptions!$I$45, AD8*(1+AD3), IF(AE7=Assumptions!$I$45, Assumptions!$P$45, 0)) -> 0 | AF8: =IF(AF7>Assumptions!$I$45, AE8*(1+AE3), IF(AF7=Assumptions!$I$45, Assumptions!$P$45, 0)) -> 5000 | AG8: =IF(AG7>Assumptions!$I$45, AF8*(1+AF3), IF(AG7=Assumptions!$I$45, Assumptions!$P$45, 0)) -> 5200 | AH8: =IF(AH7>Assumptions!$I$45, AG8*(1+AG3), IF(AH7=Assumptions!$I$45, Assumptions!$P$45, 0)) -> 5408 | AI8: =IF(AI7>Assumptions!$I$45, AH8*(1+AH3), IF(AI7=Assumptions!$I$45, Assumptions!$P$45, 0)) -> 5624.32 | AJ8: =IF(AJ7>Assumptions!$I$45, AI8*(1+AI3), IF(AJ7=Assumptions!$I$45, Assumptions!$P$45, 0)) -> 5849.2928 | AK8: =IF(AK7>Assumptions!$I$45, AJ8*(1+AJ3), IF(AK7=Assumptions!$I$45, Assumptions!$P$45, 0)) -> 6083.2645 | AL8: =IF(AL7>Assumptions!$I$45, AK8*(1+AK3), IF(AL7=Assumptions!$I$45, Assumptions!$P$45, 0)) -> 6326.5951 | AP8: Drone | AQ8: =IF(AQ7=Assumptions!$I$45, Assumptions!$D$45, 0) -> 0 | AR8: =IF(AR7>Assumptions!$I$45, AQ8*(1+AC22), IF(AR7=Assumptions!$I$45, Assumptions!$D$45, 0)) -> 0 | AS8: =IF(AS7>Assumptions!$I$45, AR8*(1+AD22), IF(AS7=Assumptions!$I$45, Assumptions!$D$45, 0)) -> 0 | AT8: =IF(AT7>Assumptions!$I$45, AS8*(1+AE22), IF(AT7=Assumptions!$I$45, Assumptions!$D$45, 0)) -> 1540 | AU8: =IF(AU7>Assumptions!$I$45, AT8*(1+AF22), IF(AU7=Assumptions!$I$45, Assumptions!$D$45, 0)) -> 1586.513 | AV8: =IF(AV7>Assumptions!$I$45, AU8*(1+AG22), IF(AV7=Assumptions!$I$45, Assumptions!$D$45, 0)) -> 1638.5199 | AW8: =IF(AW7>Assumptions!$I$45, AV8*(1+AH22), IF(AW7=Assumptions!$I$45, Assumptions!$D$45, 0)) -> 1697.5539 | AX8: =IF(AX7>Assumptions!$I$45, AW8*(1+AI22), IF(AX7=Assumptions!$I$45, Assumptions!$D$45, 0)) -> 1763.2846 | AY8: =IF(AY7>Assumptions!$I$45, AX8*(1+AJ22), IF(AY7=Assumptions!$I$45, Assumptions!$D$45, 0)) -> 1838.5712 | AZ8: =IF(AZ7>Assumptions!$I$45, AY8*(1+AK22), IF(AZ7=Assumptions!$I$45, Assumptions!$D$45, 0)) -> 1921.6894
B9: Rover | C9: =IF(C7=Assumptions!$F$46, Assumptions!$P$46, 0) -> 7000 | D9: =IF(D7>Assumptions!$F$46, C9*(1+C3), IF(D7=Assumptions!$F$46, Assumptions!$P$46, 0)) -> 7322 | E9: =IF(E7>Assumptions!$F$46, D9*(1+D3), IF(E7=Assumptions!$F$46, Assumptions!$P$46, 0)) -> 7658.812 | F9: =IF(F7>Assumptions!$F$46, E9*(1+E3), IF(F7=Assumptions!$F$46, Assumptions!$P$46, 0)) -> 8011.1174 | G9: =IF(G7>Assumptions!$F$46, F9*(1+F3), IF(G7=Assumptions!$F$46, Assumptions!$P$46, 0)) -> 8379.6288 | H9: =IF(H7>Assumptions!$F$46, G9*(1+G3), IF(H7=Assumptions!$F$46, Assumptions!$P$46, 0)) -> 8765.0917 | I9: =IF(I7>Assumptions!$F$46, H9*(1+H3), IF(I7=Assumptions!$F$46, Assumptions!$P$46, 0)) -> 9168.2859 | J9: =IF(J7>Assumptions!$F$46, I9*(1+I3), IF(J7=Assumptions!$F$46, Assumptions!$P$46, 0)) -> 9590.027 | K9: =IF(K7>Assumptions!$F$46, J9*(1+J3), IF(K7=Assumptions!$F$46, Assumptions!$P$46, 0)) -> 10031.168 | L9: =IF(L7>Assumptions!$F$46, K9*(1+K3), IF(L7=Assumptions!$F$46, Assumptions!$P$46, 0)) -> 10492.602 | P9: Rover | Q9: =IF(Q7=Assumptions!$F$46, Assumptions!$D$46, 0) -> 1000 | R9: =IF(R7>Assumptions!$F$46, Q9*(1+C23), IF(R7=Assumptions!$F$46, Assumptions!$D$46, 0)) -> 1090 | S9: =IF(S7>Assumptions!$F$46, R9*(1+D23), IF(S7=Assumptions!$F$46, Assumptions!$D$46, 0)) -> 1191.1311 | T9: =IF(T7>Assumptions!$F$46, S9*(1+E23), IF(T7=Assumptions!$F$46, Assumptions!$D$46, 0)) -> 1305.699 | U9: =IF(U7>Assumptions!$F$46, T9*(1+F23), IF(U7=Assumptions!$F$46, Assumptions!$D$46, 0)) -> 1434.6548 | V9: =IF(V7>Assumptions!$F$46, U9*(1+G23), IF(V7=Assumptions!$F$46, Assumptions!$D$46, 0)) -> 1581.3162 | W9: =IF(W7>Assumptions!$F$46, V9*(1+H23), IF(W7=Assumptions!$F$46, Assumptions!$D$46, 0)) -> 1749.1918 | X9: =IF(X7>Assumptions!$F$46, W9*(1+I23), IF(X7=Assumptions!$F$46, Assumptions!$D$46, 0)) -> 1941.7914 | Y9: =IF(Y7>Assumptions!$F$46, X9*(1+J23), IF(Y7=Assumptions!$F$46, Assumptions!$D$46, 0)) -> 2161.3431 | Z9: =IF(Z7>Assumptions!$F$46, Y9*(1+K23), IF(Z7=Assumptions!$F$46, Assumptions!$D$46, 0)) -> 2414.0286 | AB9: Rover | AC9: =IF(AC$67=Assumptions!$I$46, Assumptions!$P$46, 0) -> 0 | AD9: =IF(AD7>Assumptions!$I$46, AC9*(1+AC3), IF(AD7=Assumptions!$I$46, Assumptions!$P$46, 0)) -> 0 | AE9: =IF(AE7>Assumptions!$I$46, AD9*(1+AD3), IF(AE7=Assumptions!$I$46, Assumptions!$P$46, 0)) -> 0 | AF9: =IF(AF7>Assumptions!$I$46, AE9*(1+AE3), IF(AF7=Assumptions!$I$46, Assumptions!$P$46, 0)) -> 7000 | AG9: =IF(AG7>Assumptions!$I$46, AF9*(1+AF3), IF(AG7=Assumptions!$I$46, Assumptions!$P$46, 0)) -> 7280 | AH9: =IF(AH7>Assumptions!$I$46, AG9*(1+AG3), IF(AH7=Assumptions!$I$46, Assumptions!$P$46, 0)) -> 7571.2 | AI9: =IF(AI7>Assumptions!$I$46, AH9*(1+AH3), IF(AI7=Assumptions!$I$46, Assumptions!$P$46, 0)) -> 7874.048 | AJ9: =IF(AJ7>Assumptions!$I$46, AI9*(1+AI3), IF(AJ7=Assumptions!$I$46, Assumptions!$P$46, 0)) -> 8189.0099 | AK9: =IF(AK7>Assumptions!$I$46, AJ9*(1+AJ3), IF(AK7=Assumptions!$I$46, Assumptions!$P$46, 0)) -> 8516.5703 | AL9: =IF(AL7>Assumptions!$I$46, AK9*(1+AK3), IF(AL7=Assumptions!$I$46, Assumptions!$P$46, 0)) -> 8857.2331 | AP9: Rover | AQ9: =IF(AQ7=Assumptions!$I$45, Assumptions!$D$46, 0) -> 0 | AR9: =IF(AR7>Assumptions!$I$45, AQ9*(1+AC23), IF(AR7=Assumptions!$I$45, Assumptions!$D$46, 0)) -> 0 | AS9: =IF(AS7>Assumptions!$I$45, AR9*(1+AD23), IF(AS7=Assumptions!$I$45, Assumptions!$D$46, 0)) -> 0 | AT9: =IF(AT7>Assumptions!$I$45, AS9*(1+AE23), IF(AT7=Assumptions!$I$45, Assumptions!$D$46, 0)) -> 1000 | AU9: =IF(AU7>Assumptions!$I$45, AT9*(1+AF23), IF(AU7=Assumptions!$I$45, Assumptions!$D$46, 0)) -> 1059.8638 | AV9: =IF(AV7>Assumptions!$I$45, AU9*(1+AG23), IF(AV7=Assumptions!$I$45, Assumptions!$D$46, 0)) -> 1126.7767 | AW9: =IF(AW7>Assumptions!$I$45, AV9*(1+AH23), IF(AW7=Assumptions!$I$45, Assumptions!$D$46, 0)) -> 1201.2485 | AX9: =IF(AX7>Assumptions!$I$45, AW9*(1+AI23), IF(AX7=Assumptions!$I$45, Assumptions!$D$46, 0)) -> 1284.6965 | AY9: =IF(AY7>Assumptions!$I$45, AX9*(1+AJ23), IF(AY7=Assumptions!$I$45, Assumptions!$D$46, 0)) -> 1378.1671 | AZ9: =IF(AZ7>Assumptions!$I$45, AY9*(1+AK23), IF(AZ7=Assumptions!$I$45, Assumptions!$D$46, 0)) -> 1483.5935
B10: Edge | C10: =IF(C7=Assumptions!$F$47, Assumptions!$P$47, 0) -> 4000 | D10: =IF(D7>Assumptions!$F$47, C10*(1+C3), IF(D7=Assumptions!$F$47, Assumptions!$P$45, 0)) -> 4184 | E10: =IF(E7>Assumptions!$F$47, D10*(1+D3), IF(E7=Assumptions!$F$47, Assumptions!$P$45, 0)) -> 4376.464 | F10: =IF(F7>Assumptions!$F$47, E10*(1+E3), IF(F7=Assumptions!$F$47, Assumptions!$P$45, 0)) -> 4577.7813 | G10: =IF(G7>Assumptions!$F$47, F10*(1+F3), IF(G7=Assumptions!$F$47, Assumptions!$P$45, 0)) -> 4788.3593 | H10: =IF(H7>Assumptions!$F$47, G10*(1+G3), IF(H7=Assumptions!$F$47, Assumptions!$P$45, 0)) -> 5008.6238 | I10: =IF(I7>Assumptions!$F$47, H10*(1+H3), IF(I7=Assumptions!$F$47, Assumptions!$P$45, 0)) -> 5239.0205 | J10: =IF(J7>Assumptions!$F$47, I10*(1+I3), IF(J7=Assumptions!$F$47, Assumptions!$P$45, 0)) -> 5480.0155 | K10: =IF(K7>Assumptions!$F$47, J10*(1+J3), IF(K7=Assumptions!$F$47, Assumptions!$P$45, 0)) -> 5732.0962 | L10: =IF(L7>Assumptions!$F$47, K10*(1+K3), IF(L7=Assumptions!$F$47, Assumptions!$P$45, 0)) -> 5995.7726 | P10: Edge | Q10: =IF(Q7=Assumptions!$F$47, Assumptions!$D$47, 0) -> 1270 | R10: =IF(R7>Assumptions!$F$47, Q10*(1+C24), IF(R7=Assumptions!$F$47, Assumptions!$D$47, 0)) -> 1295.4 | S10: =IF(S7>Assumptions!$F$47, R10*(1+D24), IF(S7=Assumptions!$F$47, Assumptions!$D$47, 0)) -> 1324.8782 | T10: =IF(T7>Assumptions!$F$47, S10*(1+E24), IF(T7=Assumptions!$F$47, Assumptions!$D$47, 0)) -> 1359.2991 | U10: =IF(U7>Assumptions!$F$47, T10*(1+F24), IF(U7=Assumptions!$F$47, Assumptions!$D$47, 0)) -> 1398.8753 | V10: =IF(V7>Assumptions!$F$47, U10*(1+G24), IF(V7=Assumptions!$F$47, Assumptions!$D$47, 0)) -> 1445.0453 | W10: =IF(W7>Assumptions!$F$47, V10*(1+H24), IF(W7=Assumptions!$F$47, Assumptions!$D$47, 0)) -> 1498.1249 | X10: =IF(X7>Assumptions!$F$47, W10*(1+I24), IF(X7=Assumptions!$F$47, Assumptions!$D$47, 0)) -> 1559.078 | Y10: =IF(Y7>Assumptions!$F$47, X10*(1+J24), IF(Y7=Assumptions!$F$47, Assumptions!$D$47, 0)) -> 1627.7145 | Z10: =IF(Z7>Assumptions!$F$47, Y10*(1+K24), IF(Z7=Assumptions!$F$47, Assumptions!$D$47, 0)) -> 1705.796 | AB10: Edge | AC10: =IF(AC$67=Assumptions!$I$47, Assumptions!$P$47, 0) -> 0 | AD10: =IF(AD7>Assumptions!$I$47, AC10*(1+AC3), IF(AD7=Assumptions!$I$47, Assumptions!$P$47, 0)) -> 0 | AE10: =IF(AE7>Assumptions!$I$47, AD10*(1+AD3), IF(AE7=Assumptions!$I$47, Assumptions!$P$47, 0)) -> 0 | AF10: =IF(AF7>Assumptions!$I$47, AE10*(1+AE3), IF(AF7=Assumptions!$I$47, Assumptions!$P$47, 0)) -> 4000 | AG10: =IF(AG7>Assumptions!$I$47, AF10*(1+AF3), IF(AG7=Assumptions!$I$47, Assumptions!$P$47, 0)) -> 4160 | AH10: =IF(AH7>Assumptions!$I$47, AG10*(1+AG3), IF(AH7=Assumptions!$I$47, Assumptions!$P$47, 0)) -> 4326.4 | AI10: =IF(AI7>Assumptions!$I$47, AH10*(1+AH3), IF(AI7=Assumptions!$I$47, Assumptions!$P$47, 0)) -> 4499.456 | AJ10: =IF(AJ7>Assumptions!$I$47, AI10*(1+AI3), IF(AJ7=Assumptions!$I$47, Assumptions!$P$47, 0)) -> 4679.4342 | AK10: =IF(AK7>Assumptions!$I$47, AJ10*(1+AJ3), IF(AK7=Assumptions!$I$47, Assumptions!$P$47, 0)) -> 4866.6116 | AL10: =IF(AL7>Assumptions!$I$47, AK10*(1+AK3), IF(AL7=Assumptions!$I$47, Assumptions!$P$47, 0)) -> 5061.2761 | AP10: Edge | AQ10: =IF(AQ7=Assumptions!$I$47, Assumptions!$D$47, 0) -> 0 | AR10: =IF(AR7>Assumptions!$I$47, AQ10*(1+AC24), IF(AR7=Assumptions!$I$47, Assumptions!$D$47, 0)) -> 0 | AS10: =IF(AS7>Assumptions!$I$47, AR10*(1+AD24), IF(AS7=Assumptions!$I$47, Assumptions!$D$47, 0)) -> 0 | AT10: =IF(AT7>Assumptions!$I$47, AS10*(1+AE24), IF(AT7=Assumptions!$I$47, Assumptions!$D$47, 0)) -> 1270 | AU10: =IF(AU7>Assumptions!$I$47, AT10*(1+AF24), IF(AU7=Assumptions!$I$47, Assumptions!$D$47, 0)) -> 1320.9413 | AV10: =IF(AV7>Assumptions!$I$47, AU10*(1+AG24), IF(AV7=Assumptions!$I$47, Assumptions!$D$47, 0)) -> 1378.6799 | AW10: =IF(AW7>Assumptions!$I$47, AV10*(1+AH24), IF(AW7=Assumptions!$I$47, Assumptions!$D$47, 0)) -> 1444.3893 | AX10: =IF(AX7>Assumptions!$I$47, AW10*(1+AI24), IF(AX7=Assumptions!$I$47, Assumptions!$D$47, 0)) -> 1518.9926 | AY10: =IF(AY7>Assumptions!$I$47, AX10*(1+AJ24), IF(AY7=Assumptions!$I$47, Assumptions!$D$47, 0)) -> 1602.5893 | AZ10: =IF(AZ7>Assumptions!$I$47, AY10*(1+AK24), IF(AZ7=Assumptions!$I$47, Assumptions!$D$47, 0)) -> 1696.1658
B11: Fog | C11: =IF(C7=Assumptions!$F$48, Assumptions!$P$48, 0) -> 0 | D11: =IF(D7>Assumptions!$F$48, C11*(1+C3), IF(D7=Assumptions!$F$48, Assumptions!$P$48, 0)) -> 9500 | E11: =IF(E7>Assumptions!$F$48, D11*(1+D3), IF(E7=Assumptions!$F$48, Assumptions!$P$48, 0)) -> 9937 | F11: =IF(F7>Assumptions!$F$48, E11*(1+E3), IF(F7=Assumptions!$F$48, Assumptions!$P$48, 0)) -> 10394.102 | G11: =IF(G7>Assumptions!$F$48, F11*(1+F3), IF(G7=Assumptions!$F$48, Assumptions!$P$48, 0)) -> 10872.231 | H11: =IF(H7>Assumptions!$F$48, G11*(1+G3), IF(H7=Assumptions!$F$48, Assumptions!$P$48, 0)) -> 11372.353 | I11: =IF(I7>Assumptions!$F$48, H11*(1+H3), IF(I7=Assumptions!$F$48, Assumptions!$P$48, 0)) -> 11895.482 | J11: =IF(J7>Assumptions!$F$48, I11*(1+I3), IF(J7=Assumptions!$F$48, Assumptions!$P$48, 0)) -> 12442.674 | K11: =IF(K7>Assumptions!$F$48, J11*(1+J3), IF(K7=Assumptions!$F$48, Assumptions!$P$48, 0)) -> 13015.037 | L11: =IF(L7>Assumptions!$F$48, K11*(1+K3), IF(L7=Assumptions!$F$48, Assumptions!$P$48, 0)) -> 13613.728 | P11: Fog | Q11: =IF(Q7=Assumptions!$F$48, Assumptions!$D$48, 0) -> 0 | R11: =IF(R7>Assumptions!$F$48, Q11*(1+C25), IF(R7=Assumptions!$F$48, Assumptions!$D$48, 0)) -> 635 | S11: =IF(S7>Assumptions!$F$48, R11*(1+D25), IF(S7=Assumptions!$F$48, Assumptions!$D$48, 0)) -> 661.97592 | T11: =IF(T7>Assumptions!$F$48, S11*(1+E25), IF(T7=Assumptions!$F$48, Assumptions!$D$48, 0)) -> 692.7 | U11: =IF(U7>Assumptions!$F$48, T11*(1+F25), IF(U7=Assumptions!$F$48, Assumptions!$D$48, 0)) -> 726.80095 | V11: =IF(V7>Assumptions!$F$48, U11*(1+G25), IF(V7=Assumptions!$F$48, Assumptions!$D$48, 0)) -> 764.38275 | W11: =IF(W7>Assumptions!$F$48, V11*(1+H25), IF(W7=Assumptions!$F$48, Assumptions!$D$48, 0)) -> 806.54934 | X11: =IF(X7>Assumptions!$F$48, W11*(1+I25), IF(X7=Assumptions!$F$48, Assumptions!$D$48, 0)) -> 853.65643 | Y11: =IF(Y7>Assumptions!$F$48, X11*(1+J25), IF(Y7=Assumptions!$F$48, Assumptions!$D$48, 0)) -> 906.17049 | Z11: =IF(Z7>Assumptions!$F$48, Y11*(1+K25), IF(Z7=Assumptions!$F$48, Assumptions!$D$48, 0)) -> 964.9294 | AB11: Fog | AC11: =IF(AC$67=Assumptions!$I$48, Assumptions!$P$48, 0) -> 0 | AD11: =IF(AD7>Assumptions!$I$48, AC11*(1+AC3), IF(AD7=Assumptions!$I$48, Assumptions!$P$48, 0)) -> 0 | AE11: =IF(AE7>Assumptions!$I$48, AD11*(1+AD3), IF(AE7=Assumptions!$I$48, Assumptions!$P$48, 0)) -> 0 | AF11: =IF(AF7>Assumptions!$I$48, AE11*(1+AE3), IF(AF7=Assumptions!$I$48, Assumptions!$P$48, 0)) -> 0 | AG11: =IF(AG7>Assumptions!$I$48, AF11*(1+AF3), IF(AG7=Assumptions!$I$48, Assumptions!$P$48, 0)) -> 9500 | AH11: =IF(AH7>Assumptions!$I$48, AG11*(1+AG3), IF(AH7=Assumptions!$I$48, Assumptions!$P$48, 0)) -> 9880 | AI11: =IF(AI7>Assumptions!$I$48, AH11*(1+AH3), IF(AI7=Assumptions!$I$48, Assumptions!$P$48, 0)) -> 10275.2 | AJ11: =IF(AJ7>Assumptions!$I$48, AI11*(1+AI3), IF(AJ7=Assumptions!$I$48, Assumptions!$P$48, 0)) -> 10686.208 | AK11: =IF(AK7>Assumptions!$I$48, AJ11*(1+AJ3), IF(AK7=Assumptions!$I$48, Assumptions!$P$48, 0)) -> 11113.656 | AL11: =IF(AL7>Assumptions!$I$48, AK11*(1+AK3), IF(AL7=Assumptions!$I$48, Assumptions!$P$48, 0)) -> 11558.203 | AP11: Fog | AQ11: =IF(AQ7=Assumptions!$I$48, Assumptions!$D$48, 0) -> 0 | AR11: =IF(AR7>Assumptions!$I$48, AQ11*(1+AC25), IF(AR7=Assumptions!$I$48, Assumptions!$D$48, 0)) -> 0 | AS11: =IF(AS7>Assumptions!$I$48, AR11*(1+AD25), IF(AS7=Assumptions!$I$48, Assumptions!$D$48, 0)) -> 0 | AT11: =IF(AT7>Assumptions!$I$48, AS11*(1+AE25), IF(AT7=Assumptions!$I$48, Assumptions!$D$48, 0)) -> 0 | AU11: =IF(AU7>Assumptions!$I$48, AT11*(1+AF25), IF(AU7=Assumptions!$I$48, Assumptions!$D$48, 0)) -> 635 | AV11: =IF(AV7>Assumptions!$I$48, AU11*(1+AG25), IF(AV7=Assumptions!$I$48, Assumptions!$D$48, 0)) -> 668.7262 | AW11: =IF(AW7>Assumptions!$I$48, AV11*(1+AH25), IF(AW7=Assumptions!$I$48, Assumptions!$D$48, 0)) -> 706.48755 | AX11: =IF(AX7>Assumptions!$I$48, AW11*(1+AI25), IF(AX7=Assumptions!$I$48, Assumptions!$D$48, 0)) -> 748.48108 | AY11: =IF(AY7>Assumptions!$I$48, AX11*(1+AJ25), IF(AY7=Assumptions!$I$48, Assumptions!$D$48, 0)) -> 795.49194 | AZ11: =IF(AZ7>Assumptions!$I$48, AY11*(1+AK25), IF(AZ7=Assumptions!$I$48, Assumptions!$D$48, 0)) -> 847.57291
B12: Enterprise | C12: =IF(C7=Assumptions!$F$49, Assumptions!$P$49, 0) -> 0 | D12: =IF(D7>Assumptions!$F$49, C12*(1+C3), IF(D7=Assumptions!$F$49, Assumptions!$P$49, 0)) -> 0 | E12: =IF(E7>Assumptions!$F$49, D12*(1+D3), IF(E7=Assumptions!$F$49, Assumptions!$P$49, 0)) -> 10000 | F12: =IF(F7>Assumptions!$F$49, E12*(1+E3), IF(F7=Assumptions!$F$49, Assumptions!$P$49, 0)) -> 10460 | G12: =IF(G7>Assumptions!$F$49, F12*(1+F3), IF(G7=Assumptions!$F$49, Assumptions!$P$49, 0)) -> 10941.16 | H12: =IF(H7>Assumptions!$F$49, G12*(1+G3), IF(H7=Assumptions!$F$49, Assumptions!$P$49, 0)) -> 11444.453 | I12: =IF(I7>Assumptions!$F$49, H12*(1+H3), IF(I7=Assumptions!$F$49, Assumptions!$P$49, 0)) -> 11970.898 | J12: =IF(J7>Assumptions!$F$49, I12*(1+I3), IF(J7=Assumptions!$F$49, Assumptions!$P$49, 0)) -> 12521.56 | K12: =IF(K7>Assumptions!$F$49, J12*(1+J3), IF(K7=Assumptions!$F$49, Assumptions!$P$49, 0)) -> 13097.551 | L12: =IF(L7>Assumptions!$F$49, K12*(1+K3), IF(L7=Assumptions!$F$49, Assumptions!$P$49, 0)) -> 13700.039 | P12: Enterprise | Q12: =IF(Q7=Assumptions!$F$49, Assumptions!$D$49, 0) -> 0 | R12: =IF(R7>Assumptions!$F$49, Q12*(1+C26), IF(R7=Assumptions!$F$49, Assumptions!$D$49, 0)) -> 0 | S12: =IF(S7>Assumptions!$F$49, R12*(1+D26), IF(S7=Assumptions!$F$49, Assumptions!$D$49, 0)) -> 318 | T12: =IF(T7>Assumptions!$F$49, S12*(1+E26), IF(T7=Assumptions!$F$49, Assumptions!$D$49, 0)) -> 332.93791 | U12: =IF(U7>Assumptions!$F$49, T12*(1+F26), IF(U7=Assumptions!$F$49, Assumptions!$D$49, 0)) -> 349.53121 | V12: =IF(V7>Assumptions!$F$49, U12*(1+G26), IF(V7=Assumptions!$F$49, Assumptions!$D$49, 0)) -> 367.85598 | W12: =IF(W7>Assumptions!$F$49, V12*(1+H26), IF(W7=Assumptions!$F$49, Assumptions!$D$49, 0)) -> 388.1685 | X12: =IF(X7>Assumptions!$F$49, W12*(1+I26), IF(X7=Assumptions!$F$49, Assumptions!$D$49, 0)) -> 411.015 | Y12: =IF(Y7>Assumptions!$F$49, X12*(1+J26), IF(Y7=Assumptions!$F$49, Assumptions!$D$49, 0)) -> 436.35246 | Z12: =IF(Z7>Assumptions!$F$49, Y12*(1+K26), IF(Z7=Assumptions!$F$49, Assumptions!$D$49, 0)) -> 464.93706 | AB12: Enterprise | AC12: =IF(AC$67=Assumptions!$I$49, Assumptions!$P$49, 0) -> 0 | AD12: =IF(AD7>Assumptions!$I$49, AC12*(1+AC3), IF(AD7=Assumptions!$I$49, Assumptions!$P$49, 0)) -> 0 | AE12: =IF(AE7>Assumptions!$I$49, AD12*(1+AD3), IF(AE7=Assumptions!$I$49, Assumptions!$P$49, 0)) -> 0 | AF12: =IF(AF7>Assumptions!$I$49, AE12*(1+AE3), IF(AF7=Assumptions!$I$49, Assumptions!$P$49, 0)) -> 0 | AG12: =IF(AG7>Assumptions!$I$49, AF12*(1+AF3), IF(AG7=Assumptions!$I$49, Assumptions!$P$49, 0)) -> 0 | AH12: =IF(AH7>Assumptions!$I$49, AG12*(1+AG3), IF(AH7=Assumptions!$I$49, Assumptions!$P$49, 0)) -> 10000 | AI12: =IF(AI7>Assumptions!$I$49, AH12*(1+AH3), IF(AI7=Assumptions!$I$49, Assumptions!$P$49, 0)) -> 10400 | AJ12: =IF(AJ7>Assumptions!$I$49, AI12*(1+AI3), IF(AJ7=Assumptions!$I$49, Assumptions!$P$49, 0)) -> 10816 | AK12: =IF(AK7>Assumptions!$I$49, AJ12*(1+AJ3), IF(AK7=Assumptions!$I$49, Assumptions!$P$49, 0)) -> 11248.64 | AL12: =IF(AL7>Assumptions!$I$49, AK12*(1+AK3), IF(AL7=Assumptions!$I$49, Assumptions!$P$49, 0)) -> 11698.586 | AP12: Enterprise | AQ12: =IF(AQ7=Assumptions!$I$49, Assumptions!$D$49, 0) -> 0 | AR12: =IF(AR7>Assumptions!$I$49, AQ12*(1+AC26), IF(AR7=Assumptions!$I$49, Assumptions!$D$49, 0)) -> 0 | AS12: =IF(AS7>Assumptions!$I$49, AR12*(1+AD26), IF(AS7=Assumptions!$I$49, Assumptions!$D$49, 0)) -> 0 | AT12: =IF(AT7>Assumptions!$I$49, AS12*(1+AE26), IF(AT7=Assumptions!$I$49, Assumptions!$D$49, 0)) -> 0 | AU12: =IF(AU7>Assumptions!$I$49, AT12*(1+AF26), IF(AU7=Assumptions!$I$49, Assumptions!$D$49, 0)) -> 0 | AV12: =IF(AV7>Assumptions!$I$49, AU12*(1+AG26), IF(AV7=Assumptions!$I$49, Assumptions!$D$49, 0)) -> 318 | AW12: =IF(AW7>Assumptions!$I$49, AV12*(1+AH26), IF(AW7=Assumptions!$I$49, Assumptions!$D$49, 0)) -> 345.54318 | AX12: =IF(AX7>Assumptions!$I$49, AW12*(1+AI26), IF(AX7=Assumptions!$I$49, Assumptions!$D$49, 0)) -> 376.84305 | AY12: =IF(AY7>Assumptions!$I$49, AX12*(1+AJ26), IF(AY7=Assumptions!$I$49, Assumptions!$D$49, 0)) -> 412.47139 | AZ12: =IF(AZ7>Assumptions!$I$49, AY12*(1+AK26), IF(AZ7=Assumptions!$I$49, Assumptions!$D$49, 0)) -> 452.94248
B13: software stacks (one time) | C13: =IF(C7=Assumptions!$F$50, Assumptions!$P$50, 0) -> 1900 | D13: =IF(D7>Assumptions!$F$50, C13*(1+C3), IF(D7=Assumptions!$F$50, Assumptions!$P$50, 0)) -> 1987.4 | E13: =IF(E7>Assumptions!$F$50, D13*(1+D3), IF(E7=Assumptions!$F$50, Assumptions!$P$50, 0)) -> 2078.8204 | F13: =IF(F7>Assumptions!$F$50, E13*(1+E3), IF(F7=Assumptions!$F$50, Assumptions!$P$50, 0)) -> 2174.4461 | G13: =IF(G7>Assumptions!$F$50, F13*(1+F3), IF(G7=Assumptions!$F$50, Assumptions!$P$50, 0)) -> 2274.4707 | H13: =IF(H7>Assumptions!$F$50, G13*(1+G3), IF(H7=Assumptions!$F$50, Assumptions!$P$50, 0)) -> 2379.0963 | I13: =IF(I7>Assumptions!$F$50, H13*(1+H3), IF(I7=Assumptions!$F$50, Assumptions!$P$50, 0)) -> 2488.5347 | J13: =IF(J7>Assumptions!$F$50, I13*(1+I3), IF(J7=Assumptions!$F$50, Assumptions!$P$50, 0)) -> 2603.0073 | K13: =IF(K7>Assumptions!$F$50, J13*(1+J3), IF(K7=Assumptions!$F$50, Assumptions!$P$50, 0)) -> 2722.7457 | L13: =IF(L7>Assumptions!$F$50, K13*(1+K3), IF(L7=Assumptions!$F$50, Assumptions!$P$50, 0)) -> 2847.992 | P13: software stacks (one time) | Q13: =IF(Q7=Assumptions!$F$50, Assumptions!$D$50, 0) -> 1900 | R13: =IF(R7>Assumptions!$F$50, Q13*(1+C27), IF(R7=Assumptions!$F$50, Assumptions!$D$50, 0)) -> 1900 | S13: =IF(S7>Assumptions!$F$50, R13*(1+D27), IF(S7=Assumptions!$F$50, Assumptions!$D$50, 0)) -> 1904.5977 | T13: =IF(T7>Assumptions!$F$50, S13*(1+E27), IF(T7=Assumptions!$F$50, Assumptions!$D$50, 0)) -> 1916.1631 | U13: =IF(U7>Assumptions!$F$50, T13*(1+F27), IF(U7=Assumptions!$F$50, Assumptions!$D$50, 0)) -> 1934.3377 | V13: =IF(V7>Assumptions!$F$50, U13*(1+G27), IF(V7=Assumptions!$F$50, Assumptions!$D$50, 0)) -> 1958.9943 | W13: =IF(W7>Assumptions!$F$50, V13*(1+H27), IF(W7=Assumptions!$F$50, Assumptions!$D$50, 0)) -> 1991.7705 | X13: =IF(X7>Assumptions!$F$50, W13*(1+I27), IF(X7=Assumptions!$F$50, Assumptions!$D$50, 0)) -> 2032.9209 | Y13: =IF(Y7>Assumptions!$F$50, X13*(1+J27), IF(Y7=Assumptions!$F$50, Assumptions!$D$50, 0)) -> 2079.9934 | Z13: =IF(Z7>Assumptions!$F$50, Y13*(1+K27), IF(Z7=Assumptions!$F$50, Assumptions!$D$50, 0)) -> 2135.577 | AB13: software stacks (one time) | AC13: =IF(AC$67=Assumptions!$I$50, Assumptions!$P$50, 0) -> 0 | AD13: =IF(AD7>Assumptions!$I$50, AC13*(1+AC3), IF(AD7=Assumptions!$I$50, Assumptions!$P$50, 0)) -> 0 | AE13: =IF(AE7>Assumptions!$I$50, AD13*(1+AD3), IF(AE7=Assumptions!$I$50, Assumptions!$P$50, 0)) -> 0 | AF13: =IF(AF7>Assumptions!$I$50, AE13*(1+AE3), IF(AF7=Assumptions!$I$50, Assumptions!$P$50, 0)) -> 1900 | AG13: =IF(AG7>Assumptions!$I$50, AF13*(1+AF3), IF(AG7=Assumptions!$I$50, Assumptions!$P$50, 0)) -> 1976 | AH13: =IF(AH7>Assumptions!$I$50, AG13*(1+AG3), IF(AH7=Assumptions!$I$50, Assumptions!$P$50, 0)) -> 2055.04 | AI13: =IF(AI7>Assumptions!$I$50, AH13*(1+AH3), IF(AI7=Assumptions!$I$50, Assumptions!$P$50, 0)) -> 2137.2416 | AJ13: =IF(AJ7>Assumptions!$I$50, AI13*(1+AI3), IF(AJ7=Assumptions!$I$50, Assumptions!$P$50, 0)) -> 2222.7313 | AK13: =IF(AK7>Assumptions!$I$50, AJ13*(1+AJ3), IF(AK7=Assumptions!$I$50, Assumptions!$P$50, 0)) -> 2311.6405 | AL13: =IF(AL7>Assumptions!$I$50, AK13*(1+AK3), IF(AL7=Assumptions!$I$50, Assumptions!$P$50, 0)) -> 2404.1061 | AP13: software stacks (one time) | AQ13: =IF(AQ7=Assumptions!$I$50, Assumptions!$D$50, 0) -> 0 | AR13: =IF(AR7>Assumptions!$I$50, AQ13*(1+AC27), IF(AR7=Assumptions!$I$50, Assumptions!$D$50, 0)) -> 0 | AS13: =IF(AS7>Assumptions!$I$50, AR13*(1+AD27), IF(AS7=Assumptions!$I$50, Assumptions!$D$50, 0)) -> 0 | AT13: =IF(AT7>Assumptions!$I$50, AS13*(1+AE27), IF(AT7=Assumptions!$I$50, Assumptions!$D$50, 0)) -> 1900 | AU13: =IF(AU7>Assumptions!$I$50, AT13*(1+AF27), IF(AU7=Assumptions!$I$50, Assumptions!$D$50, 0)) -> 1922.1616 | AV13: =IF(AV7>Assumptions!$I$50, AU13*(1+AG27), IF(AV7=Assumptions!$I$50, Assumptions!$D$50, 0)) -> 1949.3125 | AW13: =IF(AW7>Assumptions!$I$50, AV13*(1+AH27), IF(AW7=Assumptions!$I$50, Assumptions!$D$50, 0)) -> 1983.0224 | AX13: =IF(AX7>Assumptions!$I$50, AW13*(1+AI27), IF(AX7=Assumptions!$I$50, Assumptions!$D$50, 0)) -> 2025.0283 | AY13: =IF(AY7>Assumptions!$I$50, AX13*(1+AJ27), IF(AY7=Assumptions!$I$50, Assumptions!$D$50, 0)) -> 2074.584 | AZ13: =IF(AZ7>Assumptions!$I$50, AY13*(1+AK27), IF(AZ7=Assumptions!$I$50, Assumptions!$D$50, 0)) -> 2133.5234
B14: software stacks (subscription) | C14: =IF(C8=Assumptions!$F$50, Assumptions!$P$51, 0) -> 0 | D14: =IF(D7>Assumptions!$F$51, C14, IF(D7=Assumptions!$F$51, Assumptions!$P$51, 0)) -> 500 | E14: =IF(E7>Assumptions!$F$51, D14, IF(E7=Assumptions!$F$51, Assumptions!$P$51, 0)) -> 500 | F14: =IF(F7>Assumptions!$F$51, E14, IF(F7=Assumptions!$F$51, Assumptions!$P$51, 0)) -> 500 | G14: =IF(G7>Assumptions!$F$51, F14, IF(G7=Assumptions!$F$51, Assumptions!$P$51, 0)) -> 500 | H14: =IF(H7>Assumptions!$F$51, G14, IF(H7=Assumptions!$F$51, Assumptions!$P$51, 0)) -> 500 | I14: =IF(I7>Assumptions!$F$51, H14, IF(I7=Assumptions!$F$51, Assumptions!$P$51, 0)) -> 500 | J14: =IF(J7>Assumptions!$F$51, I14, IF(J7=Assumptions!$F$51, Assumptions!$P$51, 0)) -> 500 | K14: =IF(K7>Assumptions!$F$51, J14, IF(K7=Assumptions!$F$51, Assumptions!$P$51, 0)) -> 500 | L14: =IF(L7>Assumptions!$F$51, K14, IF(L7=Assumptions!$F$51, Assumptions!$P$51, 0)) -> 500 | P14: software stacks (subscription) | Q14: =IF(Q7=Assumptions!$F$51, Assumptions!$D$51, 0) -> 0 | R14: =IF(R7>Assumptions!$F$51, Q14*(1-Assumptions!$V$15) + Assumptions!$D$51*(1+C27), IF(R7=Assumptions!$F$51, Assumptions!$D$51, 0)) -> 400 | S14: =IF(S7>Assumptions!$F$51, R14*(1-Assumptions!$V$15) + Assumptions!$D$51*(1+D27), IF(S7=Assumptions!$F$51, Assumptions!$D$51, 0)) -> 740.96793 | T14: =IF(T7>Assumptions!$F$51, S14*(1-Assumptions!$V$15) + Assumptions!$D$51*(1+E27), IF(T7=Assumptions!$F$51, Assumptions!$D$51, 0)) -> 1032.2517 | U14: =IF(U7>Assumptions!$F$51, T14*(1-Assumptions!$V$15) + Assumptions!$D$51*(1+F27), IF(U7=Assumptions!$F$51, Assumptions!$D$51, 0)) -> 1281.2079 | V14: =IF(V7>Assumptions!$F$51, U14*(1-Assumptions!$V$15) + Assumptions!$D$51*(1+G27), IF(V7=Assumptions!$F$51, Assumptions!$D$51, 0)) -> 1494.1254 | W14: =IF(W7>Assumptions!$F$51, V14*(1-Assumptions!$V$15) + Assumptions!$D$51*(1+H27), IF(W7=Assumptions!$F$51, Assumptions!$D$51, 0)) -> 1676.6991 | X14: =IF(X7>Assumptions!$F$51, W14*(1-Assumptions!$V$15) + Assumptions!$D$51*(1+I27), IF(X7=Assumptions!$F$51, Assumptions!$D$51, 0)) -> 1833.4583 | Y14: =IF(Y7>Assumptions!$F$51, X14*(1-Assumptions!$V$15) + Assumptions!$D$51*(1+J27), IF(Y7=Assumptions!$F$51, Assumptions!$D$51, 0)) -> 1967.7016 | Z14: =IF(Z7>Assumptions!$F$51, Y14*(1-Assumptions!$V$15) + Assumptions!$D$51*(1+K27), IF(Z7=Assumptions!$F$51, Assumptions!$D$51, 0)) -> 2083.2355 | AB14: software stacks (subscription) | AC14: =IF(AC$67=Assumptions!$I$51, Assumptions!$P$51, 0) -> 0 | AD14: =IF(AD7>Assumptions!$I$51, AC14, IF(AD7=Assumptions!$I$51, Assumptions!$P$51, 0)) -> 0 | AE14: =IF(AE7>Assumptions!$I$51, AD14, IF(AE7=Assumptions!$I$51, Assumptions!$P$51, 0)) -> 0 | AF14: =IF(AF7>Assumptions!$I$51, AE14, IF(AF7=Assumptions!$I$51, Assumptions!$P$51, 0)) -> 0 | AG14: =IF(AG7>Assumptions!$I$51, AF14, IF(AG7=Assumptions!$I$51, Assumptions!$P$51, 0)) -> 500 | AH14: =IF(AH7>Assumptions!$I$51, AG14, IF(AH7=Assumptions!$I$51, Assumptions!$P$51, 0)) -> 500 | AI14: =IF(AI7>Assumptions!$I$51, AH14, IF(AI7=Assumptions!$I$51, Assumptions!$P$51, 0)) -> 500 | AJ14: =IF(AJ7>Assumptions!$I$51, AI14, IF(AJ7=Assumptions!$I$51, Assumptions!$P$51, 0)) -> 500 | AK14: =IF(AK7>Assumptions!$I$51, AJ14, IF(AK7=Assumptions!$I$51, Assumptions!$P$51, 0)) -> 500 | AL14: =IF(AL7>Assumptions!$I$51, AK14, IF(AL7=Assumptions!$I$51, Assumptions!$P$51, 0)) -> 500 | AP14: software stacks (subscription) | AQ14: =IF(AQ7=Assumptions!$I$51, Assumptions!$D$51, 0) -> 0 | AR14: =IF(AR7>Assumptions!$I$51, AQ14*(1-Assumptions!$V$17) + Assumptions!$D$51*(1+AC27), IF(AR7=Assumptions!$I$51, Assumptions!$D$51, 0)) -> 0 | AS14: =IF(AS7>Assumptions!$I$51, AR14*(1-Assumptions!$V$17) + Assumptions!$D$51*(1+AD27), IF(AS7=Assumptions!$I$51, Assumptions!$D$51, 0)) -> 0 | AT14: =IF(AT7>Assumptions!$I$51, AS14*(1-Assumptions!$V$17) + Assumptions!$D$51*(1+AE27), IF(AT7=Assumptions!$I$51, Assumptions!$D$51, 0)) -> 0 | AU14: =IF(AU7>Assumptions!$I$51, AT14*(1-Assumptions!$V$17) + Assumptions!$D$51*(1+AF27), IF(AU7=Assumptions!$I$51, Assumptions!$D$51, 0)) -> 400 | AV14: =IF(AV7>Assumptions!$I$51, AU14*(1-Assumptions!$V$17) + Assumptions!$D$51*(1+AG27), IF(AV7=Assumptions!$I$51, Assumptions!$D$51, 0)) -> 749.65008 | AW14: =IF(AW7>Assumptions!$I$51, AV14*(1-Assumptions!$V$17) + Assumptions!$D$51*(1+AH27), IF(AW7=Assumptions!$I$51, Assumptions!$D$51, 0)) -> 1051.6164 | AX14: =IF(AX7>Assumptions!$I$51, AW14*(1-Assumptions!$V$17) + Assumptions!$D$51*(1+AI27), IF(AX7=Assumptions!$I$51, Assumptions!$D$51, 0)) -> 1312.8632 | AY14: =IF(AY7>Assumptions!$I$51, AX14*(1-Assumptions!$V$17) + Assumptions!$D$51*(1+AJ27), IF(AY7=Assumptions!$I$51, Assumptions!$D$51, 0)) -> 1538.851 | AZ14: =IF(AZ7>Assumptions!$I$51, AY14*(1-Assumptions!$V$17) + Assumptions!$D$51*(1+AK27), IF(AZ7=Assumptions!$I$51, Assumptions!$D$51, 0)) -> 1734.7759
B15: system integration | C15: =IF(C7=Assumptions!$F$52, Assumptions!$P$52, 0) -> 0 | D15: =IF(D7>Assumptions!$F$52, C15*(1+C3), IF(D7=Assumptions!$F$52, Assumptions!$P$52, 0)) -> 500 | E15: =IF(E7>Assumptions!$F$52, D15*(1+D3), IF(E7=Assumptions!$F$52, Assumptions!$P$52, 0)) -> 523 | F15: =IF(F7>Assumptions!$F$52, E15*(1+E3), IF(F7=Assumptions!$F$52, Assumptions!$P$52, 0)) -> 547.058 | G15: =IF(G7>Assumptions!$F$52, F15*(1+F3), IF(G7=Assumptions!$F$52, Assumptions!$P$52, 0)) -> 572.22267 | H15: =IF(H7>Assumptions!$F$52, G15*(1+G3), IF(H7=Assumptions!$F$52, Assumptions!$P$52, 0)) -> 598.54491 | I15: =IF(I7>Assumptions!$F$52, H15*(1+H3), IF(I7=Assumptions!$F$52, Assumptions!$P$52, 0)) -> 626.07798 | J15: =IF(J7>Assumptions!$F$52, I15*(1+I3), IF(J7=Assumptions!$F$52, Assumptions!$P$52, 0)) -> 654.87756 | K15: =IF(K7>Assumptions!$F$52, J15*(1+J3), IF(K7=Assumptions!$F$52, Assumptions!$P$52, 0)) -> 685.00193 | L15: =IF(L7>Assumptions!$F$52, K15*(1+K3), IF(L7=Assumptions!$F$52, Assumptions!$P$52, 0)) -> 716.51202 | P15: system integration | Q15: =IF(Q7=Assumptions!$F$52, Assumptions!$D$52, 0) -> 0 | R15: =IF(R7>Assumptions!$F$52, Q15*(1+C28), IF(R7=Assumptions!$F$52, Assumptions!$D$52, 0)) -> 300 | S15: =IF(S7>Assumptions!$F$52, R15*(1+D28), IF(S7=Assumptions!$F$52, Assumptions!$D$52, 0)) -> 301.11278 | T15: =IF(T7>Assumptions!$F$52, S15*(1+E28), IF(T7=Assumptions!$F$52, Assumptions!$D$52, 0)) -> 303.20058 | U15: =IF(U7>Assumptions!$F$52, T15*(1+F28), IF(U7=Assumptions!$F$52, Assumptions!$D$52, 0)) -> 306.22802 | V15: =IF(V7>Assumptions!$F$52, U15*(1+G28), IF(V7=Assumptions!$F$52, Assumptions!$D$52, 0)) -> 310.47046 | W15: =IF(W7>Assumptions!$F$52, V15*(1+H28), IF(W7=Assumptions!$F$52, Assumptions!$D$52, 0)) -> 315.55677 | X15: =IF(X7>Assumptions!$F$52, W15*(1+I28), IF(X7=Assumptions!$F$52, Assumptions!$D$52, 0)) -> 321.87588 | Y15: =IF(Y7>Assumptions!$F$52, X15*(1+J28), IF(Y7=Assumptions!$F$52, Assumptions!$D$52, 0)) -> 329.15907 | Z15: =IF(Z7>Assumptions!$F$52, Y15*(1+K28), IF(Z7=Assumptions!$F$52, Assumptions!$D$52, 0)) -> 337.79284 | AB15: system integration | AC15: =IF(AC$67=Assumptions!$I$52, Assumptions!$P$52, 0) -> 0 | AD15: =IF(AD7>Assumptions!$I$52, AC15*(1+AC3), IF(AD7=Assumptions!$I$52, Assumptions!$P$52, 0)) -> 0 | AE15: =IF(AE7>Assumptions!$I$52, AD15*(1+AD3), IF(AE7=Assumptions!$I$52, Assumptions!$P$52, 0)) -> 0 | AF15: =IF(AF7>Assumptions!$I$52, AE15*(1+AE3), IF(AF7=Assumptions!$I$52, Assumptions!$P$52, 0)) -> 0 | AG15: =IF(AG7>Assumptions!$I$52, AF15*(1+AF3), IF(AG7=Assumptions!$I$52, Assumptions!$P$52, 0)) -> 500 | AH15: =IF(AH7>Assumptions!$I$52, AG15*(1+AG3), IF(AH7=Assumptions!$I$52, Assumptions!$P$52, 0)) -> 520 | AI15: =IF(AI7>Assumptions!$I$52, AH15*(1+AH3), IF(AI7=Assumptions!$I$52, Assumptions!$P$52, 0)) -> 540.8 | AJ15: =IF(AJ7>Assumptions!$I$52, AI15*(1+AI3), IF(AJ7=Assumptions!$I$52, Assumptions!$P$52, 0)) -> 562.432 | AK15: =IF(AK7>Assumptions!$I$52, AJ15*(1+AJ3), IF(AK7=Assumptions!$I$52, Assumptions!$P$52, 0)) -> 584.92928 | AL15: =IF(AL7>Assumptions!$I$52, AK15*(1+AK3), IF(AL7=Assumptions!$I$52, Assumptions!$P$52, 0)) -> 608.32645 | AP15: system integration | AQ15: =IF(AQ7=Assumptions!$I$52, Assumptions!$D$52, 0) -> 0 | AR15: =IF(AR7>Assumptions!$F$52, AQ15*(1+AC28), IF(AR7=Assumptions!$I$52, Assumptions!$D$52, 0)) -> 0 | AS15: =IF(AS7>Assumptions!$F$52, AR15*(1+AD28), IF(AS7=Assumptions!$I$52, Assumptions!$D$52, 0)) -> 0 | AT15: =IF(AT7>Assumptions!$F$52, AS15*(1+AE28), IF(AT7=Assumptions!$I$52, Assumptions!$D$52, 0)) -> 0 | AU15: =IF(AU7>Assumptions!$F$52, AT15*(1+AF28), IF(AU7=Assumptions!$I$52, Assumptions!$D$52, 0)) -> 0 | AV15: =IF(AV7>Assumptions!$F$52, AU15*(1+AG28), IF(AV7=Assumptions!$I$52, Assumptions!$D$52, 0)) -> 0 | AW15: =IF(AW7>Assumptions!$F$52, AV15*(1+AH28), IF(AW7=Assumptions!$I$52, Assumptions!$D$52, 0)) -> 0 | AX15: =IF(AX7>Assumptions!$F$52, AW15*(1+AI28), IF(AX7=Assumptions!$I$52, Assumptions!$D$52, 0)) -> 0 | AY15: =IF(AY7>Assumptions!$F$52, AX15*(1+AJ28), IF(AY7=Assumptions!$I$52, Assumptions!$D$52, 0)) -> 0 | AZ15: =IF(AZ7>Assumptions!$F$52, AY15*(1+AK28), IF(AZ7=Assumptions!$I$52, Assumptions!$D$52, 0)) -> 0
B16: liscencing | C16: =IF(C7=Assumptions!$F$53, Assumptions!$P$53, 0) -> 0 | D16: =IF(D7>Assumptions!$F$53, C16*(1+C3), IF(D7=Assumptions!$F$53, Assumptions!$P$53, 0)) -> 300 | E16: =IF(E7>Assumptions!$F$53, D16*(1+D3), IF(E7=Assumptions!$F$53, Assumptions!$P$53, 0)) -> 313.8 | F16: =IF(F7>Assumptions!$F$53, E16*(1+E3), IF(F7=Assumptions!$F$53, Assumptions!$P$53, 0)) -> 328.2348 | G16: =IF(G7>Assumptions!$F$53, F16*(1+F3), IF(G7=Assumptions!$F$53, Assumptions!$P$53, 0)) -> 343.3336 | H16: =IF(H7>Assumptions!$F$53, G16*(1+G3), IF(H7=Assumptions!$F$53, Assumptions!$P$53, 0)) -> 359.12695 | I16: =IF(I7>Assumptions!$F$53, H16*(1+H3), IF(I7=Assumptions!$F$53, Assumptions!$P$53, 0)) -> 375.64679 | J16: =IF(J7>Assumptions!$F$53, I16*(1+I3), IF(J7=Assumptions!$F$53, Assumptions!$P$53, 0)) -> 392.92654 | K16: =IF(K7>Assumptions!$F$53, J16*(1+J3), IF(K7=Assumptions!$F$53, Assumptions!$P$53, 0)) -> 411.00116 | L16: =IF(L7>Assumptions!$F$53, K16*(1+K3), IF(L7=Assumptions!$F$53, Assumptions!$P$53, 0)) -> 429.90721 | P16: liscencing | Q16: =IF(Q7=Assumptions!$F$53, Assumptions!$D$53, 0) -> 0 | R16: =IF(R7>Assumptions!$F$53, Q16*(1+C29), IF(R7=Assumptions!$F$53, Assumptions!$D$53, 0)) -> 1500 | S16: =IF(S7>Assumptions!$F$53, R16*(1+D29), IF(S7=Assumptions!$F$53, Assumptions!$D$53, 0)) -> 1505.3138 | T16: =IF(T7>Assumptions!$F$53, S16*(1+E29), IF(T7=Assumptions!$F$53, Assumptions!$D$53, 0)) -> 1514.5467 | U16: =IF(U7>Assumptions!$F$53, T16*(1+F29), IF(U7=Assumptions!$F$53, Assumptions!$D$53, 0)) -> 1529.6971 | V16: =IF(V7>Assumptions!$F$53, U16*(1+G29), IF(V7=Assumptions!$F$53, Assumptions!$D$53, 0)) -> 1550.8971 | W16: =IF(W7>Assumptions!$F$53, V16*(1+H29), IF(W7=Assumptions!$F$53, Assumptions!$D$53, 0)) -> 1578.5657 | X16: =IF(X7>Assumptions!$F$53, W16*(1+I29), IF(X7=Assumptions!$F$53, Assumptions!$D$53, 0)) -> 1612.4646 | Y16: =IF(Y7>Assumptions!$F$53, X16*(1+J29), IF(Y7=Assumptions!$F$53, Assumptions!$D$53, 0)) -> 1653.0737 | Z16: =IF(Z7>Assumptions!$F$53, Y16*(1+K29), IF(Z7=Assumptions!$F$53, Assumptions!$D$53, 0)) -> 1700.083 | AB16: liscencing | AC16: =IF(AC$67=Assumptions!$I$53, Assumptions!$P$53, 0) -> 0 | AD16: =IF(AD7>Assumptions!$I$53, AC16*(1+AC3), IF(AD7=Assumptions!$I$53, Assumptions!$P$53, 0)) -> 0 | AE16: =IF(AE7>Assumptions!$I$53, AD16*(1+AD3), IF(AE7=Assumptions!$I$53, Assumptions!$P$53, 0)) -> 0 | AF16: =IF(AF7>Assumptions!$I$53, AE16*(1+AE3), IF(AF7=Assumptions!$I$53, Assumptions!$P$53, 0)) -> 0 | AG16: =IF(AG7>Assumptions!$I$53, AF16*(1+AF3), IF(AG7=Assumptions!$I$53, Assumptions!$P$53, 0)) -> 300 | AH16: =IF(AH7>Assumptions!$I$53, AG16*(1+AG3), IF(AH7=Assumptions!$I$53, Assumptions!$P$53, 0)) -> 312 | AI16: =IF(AI7>Assumptions!$I$53, AH16*(1+AH3), IF(AI7=Assumptions!$I$53, Assumptions!$P$53, 0)) -> 324.48 | AJ16: =IF(AJ7>Assumptions!$I$53, AI16*(1+AI3), IF(AJ7=Assumptions!$I$53, Assumptions!$P$53, 0)) -> 337.4592 | AK16: =IF(AK7>Assumptions!$I$53, AJ16*(1+AJ3), IF(AK7=Assumptions!$I$53, Assumptions!$P$53, 0)) -> 350.95757 | AL16: =IF(AL7>Assumptions!$I$53, AK16*(1+AK3), IF(AL7=Assumptions!$I$53, Assumptions!$P$53, 0)) -> 364.99587 | AP16: liscencing | AQ16: =IF(AQ7=Assumptions!$I$53, Assumptions!$D$53, 0) -> 0 | AR16: =IF(AR7>Assumptions!$I$53, AQ16*(1+AC29), IF(AR7=Assumptions!$I$53, Assumptions!$D$53, 0)) -> 0 | AS16: =IF(AS7>Assumptions!$I$53, AR16*(1+AD29), IF(AS7=Assumptions!$I$53, Assumptions!$D$53, 0)) -> 0 | AT16: =IF(AT7>Assumptions!$I$53, AS16*(1+AE29), IF(AT7=Assumptions!$I$53, Assumptions!$D$53, 0)) -> 0 | AU16: =IF(AU7>Assumptions!$I$53, AT16*(1+AF29), IF(AU7=Assumptions!$I$53, Assumptions!$D$53, 0)) -> 1500 | AV16: =IF(AV7>Assumptions!$I$53, AU16*(1+AG29), IF(AV7=Assumptions!$I$53, Assumptions!$D$53, 0)) -> 1521.7306 | AW16: =IF(AW7>Assumptions!$I$53, AV16*(1+AH29), IF(AW7=Assumptions!$I$53, Assumptions!$D$53, 0)) -> 1548.937 | AX16: =IF(AX7>Assumptions!$I$53, AW16*(1+AI29), IF(AX7=Assumptions!$I$53, Assumptions!$D$53, 0)) -> 1582.6628 | AY16: =IF(AY7>Assumptions!$I$53, AX16*(1+AJ29), IF(AY7=Assumptions!$I$53, Assumptions!$D$53, 0)) -> 1621.7024 | AZ16: =IF(AZ7>Assumptions!$I$53, AY16*(1+AK29), IF(AZ7=Assumptions!$I$53, Assumptions!$D$53, 0)) -> 1667.4294
