Workbook

Sheet Table of Contents
A1: File | B1: Electronics Manufacturing Venture | E1: Red | F1: Requires further attention
A2: Author | B2: Krishnamurthy Bindumadhavan | E2: Blue | F2: Input cells
A3: Tab | B3: Table of contents | E3: Green | F3: Cells linked to another sheet
A4: Created | B4: 46033 | E4: Black | F4: Cells containing a calculation on the same sheet
C6: Worksheets
C7: Table of Contents | E7: Input Cells | F7: Description
C8: Assumptions | E8: Yes | F8: All relevant assumptions
C9: Net Income Analysis | E9: No | F9: NI trend and related analysis
C10: Revenue Analysis | E10: No | F10: Revenue trend and related analysis
C11: Expense Analysis | E11: No | F11: Expense trend and related analysis
C12: Casflow Analysis | E12: No | F12: Cashflow trend and waterfall
C13: Income Statement | E13: No | F13: Income Statement
C14: Balance Sheet | E14: No | F14: Balance Sheet
C15: Casflow Statement | E15: No | F15: Statement of Cashflows
C16: Valuation | E16: Yes | F16: NPV and IRR calculations
C17: Loan Repayment Schedule | E17: No | F17: Loan Repayment Schedule
C18: Depreciation Schedule | E18: No | F18: Depreciation Schedule
... C20: Existing Practice Valuation | E20: Yes | F20: Valuation for purchase of existing practice
A1048543: sri rama jayam
A1048544: sri rama jayam
A1048545: sri rama jayam

Sheet Comments
C3: srj srj srj srj srj srj srj srj srj
C7: 4 product lines
C8: Far Edge | D8: Drone | E8: Rover
C9: Edge | D9: Ruggedized Laptop
C10: FOG | D10: Computer server
C11: Enterprise/ Cloud | D11: AWS
C13: India
D14: Year 1 | E14: Year 2 | F14: Year 3 | G14: Year 4 | H14: Year 5 | I14: Year 6 | J14: Year 7 | K14: Year 8 | L14: Year 9 | M14: Year 10
C15: Drone | D15: 0.06 | E15: =D15 -> 0.06 | F15: =E15 -> 0.06 | G15: =F15 -> 0.06 | H15: =G15 -> 0.06 | I15: =H15 -> 0.06 | J15: =I15 -> 0.06 | K15: =J15 -> 0.06 | L15: =K15 -> 0.06 | M15: =L15 -> 0.06
C16: Rover | D16: 0.06 | E16: =D16 -> 0.06 | F16: =E16 -> 0.06 | G16: =F16 -> 0.06 | H16: =G16 -> 0.06 | I16: =H16 -> 0.06 | J16: =I16 -> 0.06 | K16: =J16 -> 0.06 | L16: =K16 -> 0.06 | M16: =L16 -> 0.06
C17: Edge | D17: 0.06 | E17: =D17 -> 0.06 | F17: =E17 -> 0.06 | G17: =F17 -> 0.06 | H17: =G17 -> 0.06 | I17: =H17 -> 0.06 | J17: =I17 -> 0.06 | K17: =J17 -> 0.06 | L17: =K17 -> 0.06 | M17: =L17 -> 0.06
C18: Fog | D18: 0.06 | E18: =D18 -> 0.06 | F18: =E18 -> 0.06 | G18: =F18 -> 0.06 | H18: =G18 -> 0.06 | I18: =H18 -> 0.06 | J18: =I18 -> 0.06 | K18: =J18 -> 0.06 | L18: =K18 -> 0.06 | M18: =L18 -> 0.06
C19: Enterprise | D19: 0.06 | E19: =D19 -> 0.06 | F19: =E19 -> 0.06 | G19: =F19 -> 0.06 | H19: =G19 -> 0.06 | I19: =H19 -> 0.06 | J19: =I19 -> 0.06 | K19: =J19 -> 0.06 | L19: =K19 -> 0.06 | M19: =L19 -> 0.06
C21: USA
D22: Year 1 | E22: Year 2 | F22: Year 3 | G22: Year 4 | H22: Year 5 | I22: Year 6 | J22: Year 7 | K22: Year 8 | L22: Year 9 | M22: Year 10
C23: Drone
C24: Rover
C25: Edge
C26: Fog
C27: Enterprise

Sheet Assumptions
A1: File | B1: ='Table of Contents'!B1 -> Electronics Manufacturing Venture | F1: Red | G1: Requires further attention
A2: Author | B2: ='Table of Contents'!B2 -> Krishnamurthy Bindumadhavan | F2: Blue | G2: Input cells
A3: Tab | B3: Assumptions | F3: Green | G3: Cells linked to another sheet
A4: Created | B4: 46033 | F4: Black | G4: Cells containing a calculation on the same sheet
C7: No of business days | D7: =12*(30 - 8) - 10 -> 254
C8: Units per day (initial) | F8: Operating Costs
C9: Growth rate (annual) | D9: 0.06 | F9: Rent | G9: =5000*12 -> 60000
F10: Utilities | G10: =1000*12 -> 12000
C11: Annual CPI | D11: 0.03 | F11: Telephone/ Internet | G11: =100*12 -> 1200
C12: Tax rate | D12: 0.35 | F12: Courier/ postage | G12: =1000*12 -> 12000
F13: Marketing & Advertising | G13: =500*12 -> 6000
C14: Interest Rate | D14: 0.15 | F14: Insurance | G14: =500*12 -> 6000
C15: Loan Term | D15: 10 | E15: Years | F15: IT Support | G15: 1000
C16: Depreciable life | D16: 10 | E16: Years | F16: Legal/ Accountancy | G16: 1000
F17: Software Systems | G17: =500*12 -> 6000
C18: Startup Costs | F18: Salaries & Benefits cost - Staff | G18: =G28*G29*G30 -> 31200
C19: Equipment | D19: 120000 | F19: Salaries & Benefits cost - Engineers | G19: 120000
C20: Factory Fit-out | D20: 75000 | F20: Security | G20: =100*12 -> 1200
C21: Security Equipment | D21: 5000 | F21: Subscriptions/ Memberships | G21: 1000
C22: IT Installation | D22: 5000 | F22: Miscellaneous / Contingency | G22: 5000
C23: Software | D23: 5000
F24: Costs Occuring Once a Year
C25: Achitect/Designer Fees | D25: 5000 | F25: Repair/ Maintenance | G25: 5000
C26: Rental Deposit (Lease) | D26: =G9/12*3 -> 15000 | F26: Licenses / Permits | G26: 500
C27: Utilities Deposit | D27: 1000
C28: Marketing & Advertising (Launch) | D28: 5000 | F28: Staff compensation per hour | G28: 15
C29: Legal | D29: 1000 | F29: Hours worked per week (per FTE) | G29: 40
C30: Training | D30: 3000 | F30: # of weeks in a year | G30: 52
C31: Miscellaneous / Contingency | D31: 5000
C33: Product Type | D33: % Patients opting | E33: Cash Fee | F33: Insurance Fee | G33: % Cash | H33: % Insurance | I33: Fee per test
C34: Eye Test | D34: 1 | E34: 120 | F34: =2/3*E34 -> 80 | G34: 0.8 | H34: =1-G34 -> 0.2 | I34: =SUMPRODUCT(E34:F34,G34:H34) -> 112
C35: Diabetes | D35: 0.2 | E35: 200 | F35: =2/3*E35 -> 133.33333 | G35: 0.8 | H35: =1-G35 -> 0.2 | I35: =SUMPRODUCT(E35:F35,G35:H35) -> 186.66667
C36: Hypertension | D36: 0.2 | E36: 200 | F36: =2/3*E36 -> 133.33333 | G36: 0.8 | H36: =1-G36 -> 0.2 | I36: =SUMPRODUCT(E36:F36,G36:H36) -> 186.66667
C37: Glaucoma | D37: 0.1 | E37: 300 | F37: =2/3*E37 -> 200 | G37: 0.8 | H37: =1-G37 -> 0.2 | I37: =SUMPRODUCT(E37:F37,G37:H37) -> 280
C38: Dry Eye | D38: 0.3 | E38: 120 | F38: =2/3*E38 -> 80 | G38: 0.8 | H38: =1-G38 -> 0.2 | I38: =SUMPRODUCT(E38:F38,G38:H38) -> 112
C39: Macular Degeneration | D39: 0.05 | E39: 300 | F39: =2/3*E39 -> 200 | G39: 0.8 | H39: =1-G39 -> 0.2 | I39: =SUMPRODUCT(E39:F39,G39:H39) -> 280
C40: Red Eye | D40: 0.05 | E40: 120 | F40: =2/3*E40 -> 80 | G40: 0.8 | H40: =1-G40 -> 0.2 | I40: =SUMPRODUCT(E40:F40,G40:H40) -> 112
C41: Trauma | D41: 0.05 | E41: 300 | F41: =2/3*E41 -> 200 | G41: 0.8 | H41: =1-G41 -> 0.2 | I41: =SUMPRODUCT(E41:F41,G41:H41) -> 280
C42: Procedures | D42: 0.05 | E42: 500 | F42: =2/3*E42 -> 333.33333 | G42: 0.8 | H42: =1-G42 -> 0.2 | I42: =SUMPRODUCT(E42:F42,G42:H42) -> 466.66667
C44: Product | D44: Units per Year (Yr1) | E44: Annual Growth rate | F44: Start year | G44: Selling Price | H44: COGS | I44: Discounts | J44: Inventory
...

Sheet Income Statement
A1: File | B1: ='Table of Contents'!B1 -> Electronics Manufacturing Venture | E1: Red | F1: Requires further attention
A2: Author | B2: ='Table of Contents'!B2 -> Krishnamurthy Bindumadhavan | E2: Blue | F2: Input cells
A3: Tab | B3: Income Statement | E3: Green | F3: Cells linked to another sheet
A4: Created | B4: 46033 | E4: Black | F4: Cells containing a calculation on the same sheet
A6: Income Statement | C6: Year 1 | D6: Year 2 | E6: Year 3 | F6: Year 4 | G6: Year 5 | H6: Year 6 | I6: Year 7 | J6: Year 8 | K6: Year 9 | L6: Year 10
A8: Revenue
A10: No of Business days | C10: =Assumptions!$D$7 -> 254 | D10: =C10 -> 254 | E10: =D10 -> 254 | F10: =E10 -> 254 | G10: =F10 -> 254 | H10: =G10 -> 254 | I10: =H10 -> 254 | J10: =I10 -> 254 | K10: =J10 -> 254 | L10: =K10 -> 254
A12: 1.0 Product Sales
A13: By Product and by Geography
A14: 1.1 Sales - Far Edge
A15: Units Sold per Year | D15: =Assumptions!D45 -> 2540 | E15: =D15*(1+Assumptions!$E$45) -> 2921 | F15: =E15*(1+Assumptions!$E$45) -> 3359.15 | G15: =F15*(1+Assumptions!$E$45) -> 3863.0225 | H15: =G15*(1+Assumptions!$E$45) -> 4442.4759 | I15: =H15*(1+Assumptions!$E$45) -> 5108.8473 | J15: =I15*(1+Assumptions!$E$45) -> 5875.1743 | K15: =J15*(1+Assumptions!$E$45) -> 6756.4505 | L15: =K15*(1+Assumptions!$E$45) -> 7769.9181
A16: Selling Price | D16: =Assumptions!G45 -> 1000 | E16: =D16*(1+Assumptions!$D$11) -> 1030 | F16: =E16*(1+Assumptions!$D$11) -> 1060.9 | G16: =F16*(1+Assumptions!$D$11) -> 1092.727 | H16: =G16*(1+Assumptions!$D$11) -> 1125.5088 | I16: =H16*(1+Assumptions!$D$11) -> 1159.2741 | J16: =I16*(1+Assumptions!$D$11) -> 1194.0523 | K16: =J16*(1+Assumptions!$D$11) -> 1229.8739 | L16: =K16*(1+Assumptions!$D$11) -> 1266.7701
A18: Far Edge Income | C18: =C15*C16 -> 0 | D18: =D15*D16 -> 2540000 | E18: =E15*E16 -> 3008630 | F18: =F15*F16 -> 3563722.2 | G18: =G15*G16 -> 4221229 | H18: =H15*H16 -> 5000045.7 | I18: =I15*I16 -> 5922554.2 | J18: =J15*J16 -> 7015265.4 | ... L18: =L15*L16 -> 9842699.7
A20: 1.2 Sales - Edge
A21: Units Sold per Year | C21: =Assumptions!D46 -> 1270 | D21: =C21*(1+Assumptions!$E$46) -> 1460.5 | E21: =D21*(1+Assumptions!$E$46) -> 1679.575 | F21: =E21*(1+Assumptions!$E$46) -> 1931.5112 | G21: =F21*(1+Assumptions!$E$46) -> 2221.2379 | H21: =G21*(1+Assumptions!$E$46) -> 2554.4236 | I21: =H21*(1+Assumptions!$E$46) -> 2937.5872 | J21: =I21*(1+Assumptions!$E$46) -> 3378.2252 | K21: =J21*(1+Assumptions!$E$46) -> 3884.959 | L21: =K21*(1+Assumptions!$E$46) -> 4467.7029
A22: Selling Price | C22: =Assumptions!$G$46 -> 2000 | D22: =C22*(1+Assumptions!$D$11) -> 2060 | E22: =D22*(1+Assumptions!$D$11) -> 2121.8 | F22: =E22*(1+Assumptions!$D$11) -> 2185.454 | G22: =F22*(1+Assumptions!$D$11) -> 2251.0176 | H22: =G22*(1+Assumptions!$D$11) -> 2318.5481 | I22: =H22*(1+Assumptions!$D$11) -> 2388.1046 | J22: =I22*(1+Assumptions!$D$11) -> 2459.7477 | K22: =J22*(1+Assumptions!$D$11) -> 2533.5402 | L22: =K22*(1+Assumptions!$D$11) -> 2609.5464
A24: Total Edge income | C24: =C21*C22 -> 2540000 | D24: =D21*D22 -> 3008630 | E24: =E21*E22 -> 3563722.2 | F24: =F21*F22 -> 4221229 | G24: =G21*G22 -> 5000045.7 | H24: =H21*H22 -> 5922554.2 | I24: =I21*I22 -> 7015265.4 | J24: =J21*J22 -> 8309581.9 | ... L24: =L21*L22 -> 11658678
A26: 1.3 Sales - FOG
A27: Units Sold per Year | D27: =Assumptions!D47 -> 635 | E27: =D27*(1+Assumptions!$E$47) -> 698.5 | F27: =E27*(1+Assumptions!$E$47) -> 768.35 | G27: =F27*(1+Assumptions!$E$47) -> 845.185 | H27: =G27*(1+Assumptions!$E$47) -> 929.7035 | I27: =H27*(1+Assumptions!$E$47) -> 1022.6739 | J27: =I27*(1+Assumptions!$E$47) -> 1124.9412 | K27: =J27*(1+Assumptions!$E$47) -> 1237.4354 | L27: =K27*(1+Assumptions!$E$47) -> 1361.1789
A28: Selling Price | D28: =Assumptions!G47 -> 3000 | E28: =D28*(1+Assumptions!$D$11) -> 3090 | F28: =E28*(1+Assumptions!$D$11) -> 3182.7 | G28: =F28*(1+Assumptions!$D$11) -> 3278.181 | H28: =G28*(1+Assumptions!$D$11) -> 3376.5264 | I28: =H28*(1+Assumptions!$D$11) -> 3477.8222 | J28: =I28*(1+Assumptions!$D$11) -> 3582.1569 | K28: =J28*(1+Assumptions!$D$11) -> 3689.6216 | L28: =K28*(1+Assumptions!$D$11) -> 3800.3102
A30: Total FOG income | C30: =C27*C28 -> 0 | D30: =D27*D28 -> 1905000 | E30: =E27*E28 -> 2158365 | F30: =F27*F28 -> 2445427.5 | G30: =G27*G28 -> 2770669.4 | H30: =H27*H28 -> 3139168.4 | I30: =I27*I28 -> 3556677.8 | J30: =J27*J28 -> 4029716 | ... L30: =L27*L28 -> 5172902.1
A32: 1.4 Sales - Enterprise
A33: Units Sold per Year | E33: =Assumptions!D48 -> 317.5 | F33: =E33*(1+Assumptions!$E$48) -> 349.25 | G33: =F33*(1+Assumptions!$E$48) -> 384.175 | H33: =G33*(1+Assumptions!$E$48) -> 422.5925 | I33: =H33*(1+Assumptions!$E$48) -> 464.85175 | J33: =I33*(1+Assumptions!$E$48) -> 511.33693 | K33: =J33*(1+Assumptions!$E$48) -> 562.47062 | L33: =K33*(1+Assumptions!$E$48) -> 618.71768
A34: Selling Price | E34: =Assumptions!G48 -> 10000 | F34: =E34*(1+Assumptions!$D$11) -> 10300 | G34: =F34*(1+Assumptions!$D$11) -> 10609 | H34: =G34*(1+Assumptions!$D$11) -> 10927.27 | I34: =H34*(1+Assumptions!$D$11) -> 11255.088 | J34: =I34*(1+Assumptions!$D$11) -> 11592.741 | K34: =J34*(1+Assumptions!$D$11) -> 11940.523 | L34: =K34*(1+Assumptions!$D$11) -> 12298.739
A36: Total Enterprise income | C36: =C33*C34 -> 0 | D36: =D33*D34 -> 0 | E36: =E33*E34 -> 3175000 | F36: =F33*F34 -> 3597275 | G36: =G33*G34 -> 4075712.6 | H36: =H33*H34 -> 4617782.3 | I36: =I33*I34 -> 5231947.4 | J36: =J33*J34 -> 5927796.4 | ... L36: =L33*L34 -> 7609447
A38: 1.5 Sales - Product 5
A39: Units Sold per Year | C39: =Assumptions!D49 -> 0 | D39: =C39*(1+Assumptions!$E$49) -> 0 | E39: =D39*(1+Assumptions!$E$49) -> 0 | F39: =E39*(1+Assumptions!$E$49) -> 0 | G39: =F39*(1+Assumptions!$E$49) -> 0 | H39: =G39*(1+Assumptions!$E$49) -> 0 | I39: =H39*(1+Assumptions!$E$49) -> 0 | J39: =I39*(1+Assumptions!$E$49) -> 0 | K39: =J39*(1+Assumptions!$E$49) -> 0 | L39: =K39*(1+Assumptions!$E$49) -> 0
A40: Selling Price | C40: =Assumptions!$G$49 -> 0 | D40: =C40*(1+Assumptions!$D$11) -> 0 | E40: =D40*(1+[1]Assumptions!$D$11) -> 0 | F40: =E40*(1+[1]Assumptions!$D$11) -> 0 | G40: =F40*(1+[1]Assumptions!$D$11) -> 0 | H40: =G40*(1+[1]Assumptions!$D$11) -> 0 | I40: =H40*(1+[1]Assumptions!$D$11) -> 0 | J40: =I40*(1+[1]Assumptions!$D$11) -> 0 | K40: =J40*(1+[1]Assumptions!$D$11) -> 0 | L40: =K40*(1+[1]Assumptions!$D$11) -> 0
A42: Total Product 5 income | C42: =C39*C40 -> 0 | D42: =D39*D40 -> 0 | E42: =E39*E40 -> 0 | F42: =F39*F40 -> 0 | G42: =G39*G40 -> 0 | H42: =H39*H40 -> 0 | I42: =I39*I40 -> 0 | J42: =J39*J40 -> 0 | ... L42: =L39*L40 -> 0
A44: 1.6 Sales - Product 6
A45: Units Sold per Year | C45: =Assumptions!D50 -> 0 | D45: =C45*(1+Assumptions!$E$50) -> 0 | E45: =D45*(1+Assumptions!$E$50) -> 0 | F45: =E45*(1+Assumptions!$E$50) -> 0 | G45: =F45*(1+Assumptions!$E$50) -> 0 | H45: =G45*(1+Assumptions!$E$50) -> 0 | I45: =H45*(1+Assumptions!$E$50) -> 0 | J45: =I45*(1+Assumptions!$E$50) -> 0 | K45: =J45*(1+Assumptions!$E$50) -> 0 | L45: =K45*(1+Assumptions!$E$50) -> 0
A46: Selling Price | C46: =Assumptions!$G$50 -> 0 | D46: =C46*(1+Assumptions!$D$11) -> 0 | E46: =D46*(1+[1]Assumptions!$D$11) -> 0 | F46: =E46*(1+[1]Assumptions!$D$11) -> 0 | G46: =F46*(1+[1]Assumptions!$D$11) -> 0 | H46: =G46*(1+[1]Assumptions!$D$11) -> 0 | I46: =H46*(1+[1]Assumptions!$D$11) -> 0 | J46: =I46*(1+[1]Assumptions!$D$11) -> 0 | K46: =J46*(1+[1]Assumptions!$D$11) -> 0 | L46: =K46*(1+[1]Assumptions!$D$11) -> 0
A48: Total Product 6 income | C48: =C45*C46 -> 0 | D48: =D45*D46 -> 0 | E48: =E45*E46 -> 0 | F48: =F45*F46 -> 0 | G48: =G45*G46 -> 0 | H48: =H45*H46 -> 0 | I48: =I45*I46 -> 0 | J48: =J45*J46 -> 0 | ... L48: =L45*L46 -> 0
A50: 1.7 Sales - Product 7
A51: Units Sold per Year | C51: =Assumptions!D51 -> 0 | D51: =C51*(1+Assumptions!$E$51) -> 0 | E51: =D51*(1+Assumptions!$E$51) -> 0 | F51: =E51*(1+Assumptions!$E$51) -> 0 | G51: =F51*(1+Assumptions!$E$51) -> 0 | H51: =G51*(1+Assumptions!$E$51) -> 0 | I51: =H51*(1+Assumptions!$E$51) -> 0 | J51: =I51*(1+Assumptions!$E$51) -> 0 | K51: =J51*(1+Assumptions!$E$51) -> 0 | L51: =K51*(1+Assumptions!$E$51) -> 0
A52: Selling Price | C52: =Assumptions!$G$51 -> 0 | D52: =C52*(1+Assumptions!$D$11) -> 0 | E52: =D52*(1+[1]Assumptions!$D$11) -> 0 | F52: =E52*(1+[1]Assumptions!$D$11) -> 0 | G52: =F52*(1+[1]Assumptions!$D$11) -> 0 | H52: =G52*(1+[1]Assumptions!$D$11) -> 0 | I52: =H52*(1+[1]Assumptions!$D$11) -> 0 | J52: =I52*(1+[1]Assumptions!$D$11) -> 0 | K52: =J52*(1+[1]Assumptions!$D$11) -> 0 | L52: =K52*(1+[1]Assumptions!$D$11) -> 0
A54: Total Product 7 income | C54: =C51*C52 -> 0 | D54: =D51*D52 -> 0 | E54: =E51*E52 -> 0 | F54: =F51*F52 -> 0 | G54: =G51*G52 -> 0 | H54: =H51*H52 -> 0 | I54: =I51*I52 -> 0 | J54: =J51*J52 -> 0 | ... L54: =L51*L52 -> 0
A56: 1.8 Sales - Product 8
A57: Units Sold per Year | C57: =Assumptions!D52 -> 0 | D57: =C57*(1+Assumptions!$E$52) -> 0 | E57: =D57*(1+Assumptions!$E$52) -> 0 | F57: =E57*(1+Assumptions!$E$52) -> 0 | G57: =F57*(1+Assumptions!$E$52) -> 0 | H57: =G57*(1+Assumptions!$E$52) -> 0 | I57: =H57*(1+Assumptions!$E$52) -> 0 | J57: =I57*(1+Assumptions!$E$52) -> 0 | K57: =J57*(1+Assumptions!$E$52) -> 0 | L57: =K57*(1+Assumptions!$E$52) -> 0
A58: Selling Price | C58: =Assumptions!$G$52 -> 0 | D58: =C58*(1+Assumptions!$D$11) -> 0 | E58: =D58*(1+[1]Assumptions!$D$11) -> 0 | F58: =E58*(1+[1]Assumptions!$D$11) -> 0 | G58: =F58*(1+[1]Assumptions!$D$11) -> 0 | H58: =G58*(1+[1]Assumptions!$D$11) -> 0 | I58: =H58*(1+[1]Assumptions!$D$11) -> 0 | J58: =I58*(1+[1]Assumptions!$D$11) -> 0 | K58: =J58*(1+[1]Assumptions!$D$11) -> 0 | L58: =K58*(1+[1]Assumptions!$D$11) -> 0
...

Sheet Balance Sheet
A1: File | B1: ='Table of Contents'!B1 -> Electronics Manufacturing Venture | F1: Red | G1: Requires further attention
A2: Author | B2: ='Table of Contents'!B2 -> Krishnamurthy Bindumadhavan | F2: Blue | G2: Input cells
A3: Tab | B3: Balance Sheet | F3: Green | G3: Cells linked to another sheet
A4: Created | B4: 46033 | F4: Black | G4: Cells containing a calculation on the same sheet
C7: Balance Sheet | H7: Projected Financials
H8: Year 1 | I8: Year 2 | J8: Year 3 | K8: Year 4 | L8: Year 5 | M8: Year 6 | N8: Year 7 | O8: Year 8 | P8: Year 9 | Q8: Year 10
D9: Assets
E10: Cash and Equivalents | H10: ='Cashflow Statement'!H36 -> 806323.79 | I10: ='Cashflow Statement'!I36 -> 4453654.8 | J10: ='Cashflow Statement'!J36 -> 12708579 | K10: ='Cashflow Statement'!K36 -> 26357284 | L10: ='Cashflow Statement'!L36 -> 46317557 | M10: ='Cashflow Statement'!M36 -> 73661180 | N10: ='Cashflow Statement'!N36 -> 1.0964021e+08 | O10: ='Cashflow Statement'!O36 -> 1.5571784e+08 | ... Q10: ='Cashflow Statement'!Q36 -> 2.8530072e+08
E11: Accounts Receivable | H11: 0 | I11: 0 | J11: 0 | K11: 0 | L11: 0 | M11: 0 | N11: 0 | O11: 0 | P11: 0 | Q11: 0
E12: Inventory | H12: =SUM(Assumptions!J45:J53) -> 381000 | I12: =H12 -> 381000 | J12: =I12 -> 381000 | K12: =J12 -> 381000 | L12: =K12 -> 381000 | M12: =L12 -> 381000 | N12: =M12 -> 381000 | O12: =N12 -> 381000 | P12: =O12 -> 381000 | Q12: =P12 -> 381000
E13: Other Current Assets | H13: 0 | I13: 0 | J13: 0 | K13: 0 | L13: 0 | M13: 0 | N13: 0 | O13: 0 | P13: 0 | Q13: 0
D14: Total Current Assets | H14: =SUM(H10:H13) -> 1187323.8 | I14: =SUM(I10:I13) -> 4834654.8 | J14: =SUM(J10:J13) -> 13089579 | K14: =SUM(K10:K13) -> 26738284 | L14: =SUM(L10:L13) -> 46698557 | M14: =SUM(M10:M13) -> 74042180 | N14: =SUM(N10:N13) -> 1.1002121e+08 | O14: =SUM(O10:O13) -> 1.5609884e+08 | ... Q14: =SUM(Q10:Q13) -> 2.8568172e+08
E17: Net Property, Plant & Equipment | H17: ='Depreciation Schedule'!G12 -> 185500 | I17: ='Depreciation Schedule'!H12 -> 164888.89 | J17: ='Depreciation Schedule'!I12 -> 144277.78 | K17: ='Depreciation Schedule'!J12 -> 123666.67 | L17: ='Depreciation Schedule'!K12 -> 103055.56 | M17: ='Depreciation Schedule'!L12 -> 82444.444 | N17: ='Depreciation Schedule'!M12 -> 61833.333 | O17: ='Depreciation Schedule'!N12 -> 41222.222 | ... Q17: ='Depreciation Schedule'!P12 -> 0
E18: Other Non-Current Assets | H18: 0 | I18: 0 | J18: 0 | K18: 0 | L18: 0 | M18: 0 | N18: 0 | O18: 0 | P18: 0 | Q18: 0
D19: Total Non-Current Assets | H19: =H17+H18 -> 185500 | I19: =I17+I18 -> 164888.89 | J19: =J17+J18 -> 144277.78 | K19: =K17+K18 -> 123666.67 | L19: =L17+L18 -> 103055.56 | M19: =M17+M18 -> 82444.444 | N19: =N17+N18 -> 61833.333 | O19: =O17+O18 -> 41222.222 | ... Q19: =Q17+Q18 -> 0
E21: Total Assets | H21: =H19+H14 -> 1372823.8 | I21: =I19+I14 -> 4999543.7 | J21: =J19+J14 -> 13233856 | K21: =K19+K14 -> 26861951 | L21: =L19+L14 -> 46801612 | M21: =M19+M14 -> 74124624 | N21: =N19+N14 -> 1.1008305e+08 | O21: =O19+O14 -> 1.5614006e+08 | ... Q21: =Q19+Q14 -> 2.8568172e+08
D23: Liabilities and Shareholders' Equity
E24: Accounts Payable | H24: 0 | I24: 0 | J24: 0 | K24: 0 | L24: 0 | M24: 0 | N24: 0 | O24: 0 | P24: 0 | Q24: 0
E25: Dividends Payable | H25: 0 | I25: 0 | J25: 0 | K25: 0 | L25: 0 | M25: 0 | N25: 0 | O25: 0 | P25: 0 | Q25: 0
E26: Short Term Debt | H26: 0 | I26: 0 | J26: 0 | K26: 0 | L26: 0 | M26: 0 | N26: 0 | O26: 0 | P26: 0 | Q26: 0
E27: Current Liabilities | H27: =SUM(H24:H26) -> 0 | I27: =SUM(I24:I26) -> 0 | J27: =SUM(J24:J26) -> 0 | K27: =SUM(K24:K26) -> 0 | L27: =SUM(L24:L26) -> 0 | M27: =SUM(M24:M26) -> 0 | N27: =SUM(N24:N26) -> 0 | O27: =SUM(O24:O26) -> 0 | ... Q27: =SUM(Q24:Q26) -> 0
E29: Long Term Debt | H29: ='Loan Repayment Schedule'!H26 -> 512012.95 | I29: ='Loan Repayment Schedule'!I26 -> 482880.14 | J29: ='Loan Repayment Schedule'!J26 -> 449064.1 | K29: ='Loan Repayment Schedule'!K26 -> 409811.98 | L29: ='Loan Repayment Schedule'!L26 -> 364249.91 | M29: ='Loan Repayment Schedule'!M26 -> 311363.52 | N29: ='Loan Repayment Schedule'!N26 -> 249975.41 | O29: ='Loan Repayment Schedule'!O26 -> 178718.89 | ... Q29: ='Loan Repayment Schedule'!Q26 -> -8.7311491e-10
E30: Non-Current Liabilities | H30: =H29 -> 512012.95 | I30: =I29 -> 482880.14 | J30: =J29 -> 449064.1 | K30: =K29 -> 409811.98 | L30: =L29 -> 364249.91 | M30: =M29 -> 311363.52 | N30: =N29 -> 249975.41 | O30: =O29 -> 178718.89 | ... Q30: =Q29 -> -8.7311491e-10
E32: Total Liabilities | H32: =H30+H27 -> 512012.95 | I32: =I30+I27 -> 482880.14 | J32: =J30+J27 -> 449064.1 | K32: =K30+K27 -> 409811.98 | L32: =L30+L27 -> 364249.91 | M32: =M30+M27 -> 311363.52 | N32: =N30+N27 -> 249975.41 | O32: =O30+O27 -> 178718.89 | ... Q32: =Q30+Q27 -> -8.7311491e-10
D34: Shareholders' Equity
E35: Common Stock | H35: 50000 | I35: =H35 -> 50000 | J35: =I35 -> 50000 | K35: =J35 -> 50000 | L35: =K35 -> 50000 | M35: =L35 -> 50000 | N35: =M35 -> 50000 | O35: =N35 -> 50000 | P35: =O35 -> 50000 | Q35: =P35 -> 50000
E36: Preferred Stock | H36: 0 | I36: 0 | J36: 0 | K36: 0 | L36: 0 | M36: 0 | N36: 0 | O36: 0 | P36: 0 | Q36: 0
E37: Accumulated earnings (deficit) | H37: ='Income Statement'!C149 -> 810810.84 | I37: ='Income Statement'!D149 -> 3655852.7 | J37: ='Income Statement'!E149 -> 8268128.8 | K37: ='Income Statement'!F149 -> 13667346 | L37: ='Income Statement'!G149 -> 19985224 | M37: ='Income Statement'!H149 -> 27375899 | N37: ='Income Statement'!I149 -> 36019811 | O37: ='Income Statement'!J149 -> 46128269 | ... Q37: ='Income Statement'!L149 -> 71771558
D38: Total Shareholder's Equity | H38: =SUM(H35:H37) -> 860810.84 | I38: =H38+I37 -> 4516663.5 | J38: =I38+J37 -> 12784792 | K38: =J38+K37 -> 26452139 | L38: =K38+L37 -> 46437362 | M38: =L38+M37 -> 73813261 | N38: =M38+N37 -> 1.0983307e+08 | O38: =N38+O37 -> 1.5596134e+08 | P38: =O38+P37 -> 2.1391016e+08 | Q38: =P38+Q37 -> 2.8568172e+08
D40: Total Liabilities & Shareholder's Equity | H40: =H38+H32 -> 1372823.8 | I40: =I38+I32 -> 4999543.7 | J40: =J38+J32 -> 13233856 | K40: =K38+K32 -> 26861951 | L40: =L38+L32 -> 46801612 | M40: =M38+M32 -> 74124624 | N40: =N38+N32 -> 1.1008305e+08 | O40: =O38+O32 -> 1.5614006e+08 | ... Q40: =Q38+Q32 -> 2.8568172e+08
D42: Balance Sheet Check | H42: =IF(ROUNDUP(H21, 0) = ROUNDUP(H40, 0), "OK", "Error") -> OK | I42: =IF(ROUNDUP(I21, 0) = ROUNDUP(I40, 0), "OK", "Error") -> OK | J42: =IF(ROUNDUP(J21, 0) = ROUNDUP(J40, 0), "OK", "Error") -> OK | K42: =IF(ROUNDUP(K21, 0) = ROUNDUP(K40, 0), "OK", "Error") -> OK | L42: =IF(ROUNDUP(L21, 0) = ROUNDUP(L40, 0), "OK", "Error") -> OK | M42: =IF(ROUNDUP(M21, 0) = ROUNDUP(M40, 0), "OK", "Error") -> OK | N42: =IF(ROUNDUP(N21, 0) = ROUNDUP(N40, 0), "OK", "Error") -> OK | O42: =IF(ROUNDUP(O21, 0) = ROUNDUP(O40, 0), "OK", "Error") -> OK | ... Q42: =IF(ROUNDUP(Q21, 0) = ROUNDUP(Q40, 0), "OK", "Error") -> OK

Sheet Cashflow Statement
A1: File | B1: ='Table of Contents'!B1 -> Electronics Manufacturing Venture | F1: Red | G1: Requires further attention
A2: Author | B2: ='Table of Contents'!B2 -> Krishnamurthy Bindumadhavan | F2: Blue | G2: Input cells
A3: Tab | B3: Cashflow Statement | F3: Green | G3: Cells linked to another sheet
A4: Created | B4: 41730 | F4: Black | G4: Cells containing a calculation on the same sheet
C6: Cash Flow Statement | H6: Projected Financials
H7: Year 1 | I7: Year 2 | J7: Year 3 | K7: Year 4 | L7: Year 5 | M7: Year 6 | N7: Year 7 | O7: Year 8 | P7: Year 9 | Q7: Year 10
C9: Net Income | H9: ='Income Statement'!C149 -> 810810.84 | I9: ='Income Statement'!D149 -> 3655852.7 | J9: ='Income Statement'!E149 -> 8268128.8 | K9: ='Income Statement'!F149 -> 13667346 | L9: ='Income Statement'!G149 -> 19985224 | M9: ='Income Statement'!H149 -> 27375899 | N9: ='Income Statement'!I149 -> 36019811 | O9: ='Income Statement'!J149 -> 46128269 | ... Q9: ='Income Statement'!L149 -> 71771558
C10: (+) Depreciation & Amortization | H10: ='Income Statement'!C136+'Income Statement'!C137 -> 20611.111 | I10: ='Income Statement'!D136+'Income Statement'!D137 -> 20611.111 | J10: ='Income Statement'!E136+'Income Statement'!E137 -> 20611.111 | K10: ='Income Statement'!F136+'Income Statement'!F137 -> 20611.111 | L10: ='Income Statement'!G136+'Income Statement'!G137 -> 20611.111 | M10: ='Income Statement'!H136+'Income Statement'!H137 -> 20611.111 | N10: ='Income Statement'!I136+'Income Statement'!I137 -> 20611.111 | O10: ='Income Statement'!J136+'Income Statement'!J137 -> 20611.111 | ... Q10: ='Income Statement'!L136+'Income Statement'!L137 -> 20611.111
C11: (Increase)/Decrease in Accounts Receivable
C12: (Increase)/Decrease in Inventory | H12: =0-'Balance Sheet'!H12 -> -381000 | I12: ='Balance Sheet'!I12-'Balance Sheet'!H12 -> 0 | J12: ='Balance Sheet'!J12-'Balance Sheet'!I12 -> 0 | K12: ='Balance Sheet'!K12-'Balance Sheet'!J12 -> 0 | L12: ='Balance Sheet'!L12-'Balance Sheet'!K12 -> 0 | M12: ='Balance Sheet'!M12-'Balance Sheet'!L12 -> 0 | N12: ='Balance Sheet'!N12-'Balance Sheet'!M12 -> 0 | O12: ='Balance Sheet'!O12-'Balance Sheet'!N12 -> 0 | P12: ='Balance Sheet'!P12-'Balance Sheet'!O12 -> 0 | Q12: ='Balance Sheet'!Q12-'Balance Sheet'!P12 -> 0
C13: (Increase)/Decrease in Other Current Assets
C14: Increase/(Decrease) in Accounts Payable
C16: Increase/(Decrease) in Accrued Expenses & Other Current Liabilities
C17: Total Cash Flow from Operating Activities | H17: =H9+H10+H12 -> 450421.95 | I17: =I9+I10+I12 -> 3676463.8 | J17: =J9+J10+J12 -> 8288739.9 | K17: =K9+K10+K12 -> 13687957 | L17: =L9+L10+L12 -> 20005835 | M17: =M9+M10+M12 -> 27396510 | N17: =N9+N10+N12 -> 36040422 | O17: =O9+O10+O12 -> 46148880 | ... Q17: =Q9+Q10+Q12 -> 71792169
C20: (-) Capital Expenditures on PP&E | H20: =-'Depreciation Schedule'!G9 -> -206111.11 | I20: 0 | J20: 0 | K20: 0 | L20: 0 | M20: 0 | N20: 0 | O20: 0 | P20: 0 | Q20: 0
C21: (-) Capital Expenditures on Other Non-Current Assets
C22: Total Cash Flow from Investing Activities | H22: =H20 -> -206111.11 | I22: =I20 -> 0 | J22: =J20 -> 0 | K22: =K20 -> 0 | L22: =L20 -> 0 | M22: =M20 -> 0 | N22: =N20 -> 0 | O22: =O20 -> 0 | ... Q22: =Q20 -> 0
C24: Proceeds from LT Loan | H24: ='Loan Repayment Schedule'!H13 -> 537111.11 | I24: 0 | J24: 0 | K24: 0 | L24: 0 | M24: 0 | N24: 0 | O24: 0 | P24: 0 | Q24: 0
C25: Payment of LT Debt | H25: =-'Loan Repayment Schedule'!H25 -> -25098.165 | I25: =-'Loan Repayment Schedule'!I25 -> -29132.808 | J25: =-'Loan Repayment Schedule'!J25 -> -33816.038 | K25: =-'Loan Repayment Schedule'!K25 -> -39252.119 | L25: =-'Loan Repayment Schedule'!L25 -> -45562.075 | M25: =-'Loan Repayment Schedule'!M25 -> -52886.384 | N25: =-'Loan Repayment Schedule'!N25 -> -61388.109 | O25: =-'Loan Repayment Schedule'!O25 -> -71256.525 | ... Q25: =-'Loan Repayment Schedule'!Q25 -> -96007.554
C26: (-) Payment of Secured Debt
C27: Increase/(Decrease) in Common Stock | H27: ='Balance Sheet'!H35 -> 50000 | I27: 0 | J27: 0 | K27: 0 | L27: 0 | M27: 0 | N27: 0 | O27: 0 | P27: 0 | Q27: 0
C28: Increase/(Decrease) in Common Dividends Payable | H28: 0 | I28: 0 | J28: 0 | K28: 0 | L28: 0 | M28: 0 | N28: 0 | O28: 0 | P28: 0 | Q28: 0
C29: Changes in Long Term Debt
C30: Total Cash Flow from Financing Activities | H30: =SUM(H24:H29) -> 562012.95 | I30: =SUM(I24:I29) -> -29132.808 | J30: =SUM(J24:J29) -> -33816.038 | K30: =SUM(K24:K29) -> -39252.119 | L30: =SUM(L24:L29) -> -45562.075 | M30: =SUM(M24:M29) -> -52886.384 | N30: =SUM(N24:N29) -> -61388.109 | O30: =SUM(O24:O29) -> -71256.525 | ... Q30: =SUM(Q24:Q29) -> -96007.554
C32: Change in Cash Balance | H32: =H17+H22+H30 -> 806323.79 | I32: =I17+I22+I30 -> 3647331 | J32: =J17+J22+J30 -> 8254923.8 | K32: =K17+K22+K30 -> 13648705 | L32: =L17+L22+L30 -> 19960273 | M32: =M17+M22+M30 -> 27343623 | N32: =N17+N22+N30 -> 35979034 | O32: =O17+O22+O30 -> 46077623 | ... Q32: =Q17+Q22+Q30 -> 71696161
C34: Opening Cash Balance | H34: 0 | I34: =H36 -> 806323.79 | J34: =I36 -> 4453654.8 | K34: =J36 -> 12708579 | L34: =K36 -> 26357284 | M34: =L36 -> 46317557 | N34: =M36 -> 73661180 | O34: =N36 -> 1.0964021e+08 | P34: =O36 -> 1.5571784e+08 | Q34: =P36 -> 2.1360455e+08
C36: Ending Cash | H36: =H32-H34 -> 806323.79 | I36: =I32+I34 -> 4453654.8 | J36: =J32+J34 -> 12708579 | K36: =K32+K34 -> 26357284 | L36: =L32+L34 -> 46317557 | M36: =M32+M34 -> 73661180 | N36: =N32+N34 -> 1.0964021e+08 | O36: =O32+O34 -> 1.5571784e+08 | P36: =P32+P34 -> 2.1360455e+08 | Q36: =Q32+Q34 -> 2.8530072e+08

Sheet Valuation
A1: File | B1: ='Table of Contents'!B1 -> Electronics Manufacturing Venture | F1: Red | G1: Requires further attention | K1: Required Return | L1: 0.15
A2: Author | B2: ='Table of Contents'!B2 -> Krishnamurthy Bindumadhavan | F2: Blue | G2: Input cells | K2: LT Growth Rate | L2: 0.03
A3: Tab | B3: Valuation | F3: Green | G3: Cells linked to another sheet | K3: TV to be included | L3: =IF('[2]Assumptions(Ops)'!C53=1, "Yes", "No") -> No
A4: Created | B4: 46033 | F4: Black | G4: Cells containing a calculation on the same sheet
G7: 0 | H7: 1 | I7: =H7+1 -> 2 | J7: =I7+1 -> 3 | K7: =J7+1 -> 4 | L7: =K7+1 -> 5 | M7: =L7+1 -> 6 | N7: =M7+1 -> 7 | O7: =N7+1 -> 8 | P7: =O7+1 -> 9 | Q7: =P7+1 -> 10
C8: Net Present Value Calculation
C9: Valuation- FCFE | G9: Year 0 | H9: Year 1 | I9: Year 2 | J9: Year 3 | K9: Year 4 | L9: Year 5 | M9: Year 6 | N9: Year 7 | O9: Year 8 | P9: Year 9 | Q9: Year 10
C11: Preferred Stock Issuance (Repayment) | H11: ='[2]Preferred Investment'!F17 -> 8000000 | I11: ='[2]Preferred Investment'!G17 -> 0 | J11: ='[2]Preferred Investment'!H17 -> 0 | K11: ='[2]Preferred Investment'!I17 -> 0 | L11: ='[2]Preferred Investment'!J17 -> 0 | M11: ='[2]Preferred Investment'!K17 -> 0 | N11: ='[2]Preferred Investment'!L17 -> 0 | O11: ='[2]Preferred Investment'!M17 -> 0 | P11: ='[2]Preferred Investment'!N17 -> 0 | Q11: ='[2]Preferred Investment'!BM17 -> 0
C12: Net Income (Common Share Holders) | G12: 0 | H12: ='Income Statement'!C147 -> 810810.84 | I12: ='Income Statement'!D147 -> 2845041.8 | J12: ='Income Statement'!E147 -> 4612276.1 | K12: ='Income Statement'!F147 -> 5399217.6 | L12: ='Income Statement'!G147 -> 6317877.3 | M12: ='Income Statement'!H147 -> 7390674.8 | N12: ='Income Statement'!I147 -> 8643912.3 | O12: ='Income Statement'!J147 -> 10108458 | ... Q12: ='Income Statement'!L147 -> 13822740
C13: Depreciation | G13: 0 | H13: ='Depreciation Schedule'!G10 -> 20611.111 | I13: ='Depreciation Schedule'!H10 -> 20611.111 | J13: ='Depreciation Schedule'!I10 -> 20611.111 | K13: ='Depreciation Schedule'!J10 -> 20611.111 | L13: ='Depreciation Schedule'!K10 -> 20611.111 | M13: ='Depreciation Schedule'!L10 -> 20611.111 | N13: ='Depreciation Schedule'!M10 -> 20611.111 | O13: ='Depreciation Schedule'!N10 -> 20611.111 | ... Q13: ='Depreciation Schedule'!P10 -> 20611.111
C14: Working Capital Investment | G14: =SUM('Balance Sheet'!H11:H13)-'Balance Sheet'!H27 -> 381000 | H14: =(SUM('Balance Sheet'!H11:H13)-'Balance Sheet'!H27)-G14 -> 0 | I14: =(SUM('Balance Sheet'!I11:I13)-'Balance Sheet'!I27)-(SUM('Balance Sheet'!H11:H13)-'Balance Sheet'!H27) -> 0 | J14: =(SUM('[1]Balance Sheet'!J11:J13)-'[1]Balance Sheet'!J27)-(SUM('[1]Balance Sheet'!I11:I13)-'[1]Balance Sheet'!I27) -> 0 | K14: =(SUM('[1]Balance Sheet'!K11:K13)-'[1]Balance Sheet'!K27)-(SUM('[1]Balance Sheet'!J11:J13)-'[1]Balance Sheet'!J27) -> 0 | L14: =(SUM('[1]Balance Sheet'!L11:L13)-'[1]Balance Sheet'!L27)-(SUM('[1]Balance Sheet'!K11:K13)-'[1]Balance Sheet'!K27) -> 0 | M14: =(SUM('[1]Balance Sheet'!M11:M13)-'[1]Balance Sheet'!M27)-(SUM('[1]Balance Sheet'!L11:L13)-'[1]Balance Sheet'!L27) -> 0 | N14: =(SUM('[1]Balance Sheet'!N11:N13)-'[1]Balance Sheet'!N27)-(SUM('[1]Balance Sheet'!M11:M13)-'[1]Balance Sheet'!M27) -> 0 | O14: =(SUM('[1]Balance Sheet'!O11:O13)-'[1]Balance Sheet'!O27)-(SUM('[1]Balance Sheet'!N11:N13)-'[1]Balance Sheet'!N27) -> 0 | P14: =(SUM('[1]Balance Sheet'!P11:P13)-'[1]Balance Sheet'!P27)-(SUM('[1]Balance Sheet'!O11:O13)-'[1]Balance Sheet'!O27) -> 0 | Q14: =(SUM('[1]Balance Sheet'!Q11:Q13)-'[1]Balance Sheet'!Q27)-(SUM('[1]Balance Sheet'!P11:P13)-'[1]Balance Sheet'!P27) -> 0
C15: Capital Expenditure | G15: ='Depreciation Schedule'!G9 -> 206111.11 | H15: 0 | I15: 0 | J15: 0 | K15: 0 | L15: 0 | M15: 0 | N15: 0 | O15: 0 | P15: 0 | Q15: 0
C16: Net Debt | G16: ='Loan Repayment Schedule'!G34 -> 537111.11 | H16: ='Loan Repayment Schedule'!H34 -> 512012.95 | I16: ='Loan Repayment Schedule'!I34 -> 482880.14 | J16: ='Loan Repayment Schedule'!J34 -> 449064.1 | K16: ='Loan Repayment Schedule'!K34 -> 409811.98 | L16: ='Loan Repayment Schedule'!L34 -> 364249.91 | M16: ='Loan Repayment Schedule'!M34 -> 311363.52 | N16: ='Loan Repayment Schedule'!N34 -> 249975.41 | ... Q16: ='Loan Repayment Schedule'!Q34 -> -8.7311491e-10
C18: Free Cash Flow to Equity | G18: =G12+G13-G14-G15+G16 -> -50000 | H18: =H12+H13-H14-H15+H16 -> 1343434.9 | I18: =I12+I13-I14-I15+I16 -> 3348533.1 | J18: =J12+J13-J14-J15+J16 -> 5081951.3 | K18: =K12+K13-K14-K15+K16 -> 5829640.7 | L18: =L12+L13-L14-L15+L16 -> 6702738.4 | M18: =M12+M13-M14-M15+M16 -> 7722649.4 | N18: =N12+N13-N14-N15+N16 -> 8914498.9 | ... Q18: =Q12+Q13-Q14-Q15+Q16 -> 13843351
C19: Terminal Value | Q19: =IF('[2]Assumptions(Ops)'!C53=0, 0, AVERAGE(Q18:Q18)*(1+($L$2/12))/(($L$1/12)-($L$2/12))) -> 0
C21: Total F.C.F.E | G21: =G18+G19 -> -50000 | H21: =H18+H19 -> 1343434.9 | I21: =I18+I19 -> 3348533.1 | J21: =J18+J19 -> 5081951.3 | K21: =K18+K19 -> 5829640.7 | L21: =L18+L19 -> 6702738.4 | M21: =M18+M19 -> 7722649.4 | N21: =N18+N19 -> 8914498.9 | ... Q21: =Q18+Q19 -> 13843351
C23: Present Value of Cash Flows | G23: =G21/((1+($L$1))^G7) -> -50000 | H23: =H21/((1+($L$1))^H7) -> 1168204.3 | I23: =I21/((1+($L$1))^I7) -> 2531972.1 | J23: =J21/((1+($L$1))^J7) -> 3341465.5 | K23: =K21/((1+($L$1))^K7) -> 3333116 | L23: =L21/((1+($L$1))^L7) -> 3332445.6 | M23: =M21/((1+($L$1))^M7) -> 3338714.5 | N23: =N21/((1+($L$1))^N7) -> 3351290.3 | ... Q23: =Q21/((1+($L$1))^Q7) -> 3421864.6
C25: NPV | F25: =SUM(G23:Q23) -> 30531995
C27: IRR | F27: =IF(ISERROR(IRR(G21:Q21)),0,IF(IRR(G21:Q21)<0,0,IRR(G21:Q21))) -> 28.279389

Sheet Net Income Analysis
A1: File | B1: ='Table of Contents'!B1 -> Electronics Manufacturing Venture | E1: Red | F1: Requires further attention
A2: Author | B2: ='Table of Contents'!B2 -> Krishnamurthy Bindumadhavan | E2: Blue | F2: Input cells
A3: Tab | B3: Net Income Analysis | E3: Green | F3: Cells linked to another sheet
A4: Created | B4: 46033 | E4: Black | F4: Cells containing a calculation on the same sheet
C7: Metric | E7: 2015 | F7: 2016 | G7: 2017 | H7: 2018 | I7: 2019 | J7: CAGR *
C8: Revenue | E8: ='[3]Revenue Analysis'!D13 -> 95000 | F8: ='[3]Revenue Analysis'!E13 -> 100000 | G8: ='[3]Revenue Analysis'!F13 -> 105000 | H8: ='[3]Revenue Analysis'!G13 -> 105000 | I8: ='[3]Revenue Analysis'!H13 -> 105000 | J8: =+(I8/E8)^(1/4)-1 -> 0.025336514 | L8: =SUM(E8:I8) -> 510000
C9: Expenses | E9: ='[3]Expense Analysis'!D14 -> 88695.63 | F9: ='[3]Expense Analysis'!E14 -> 91148.092 | G9: ='[3]Expense Analysis'!F14 -> 93700.472 | H9: ='[3]Expense Analysis'!G14 -> 96356.84 | I9: ='[3]Expense Analysis'!H14 -> 99121.433 | J9: =+(I9/E9)^(1/4)-1 -> 0.028173337 | L9: =SUM(E9:I9) -> 469022.47
C10: Net Income | E10: =E8-E9 -> 6304.3703 | F10: =F8-F9 -> 8851.9075 | G10: =G8-G9 -> 11299.528 | H10: =H8-H9 -> 8643.1597 | I10: =I8-I9 -> 5878.5673 | L10: =SUM(E10:I10) -> 40977.532 | M10: =L10/L8 -> 0.080348103
C11: Profit Margin | E11: =E10/E8 -> 0.066361793 | F11: =F10/F8 -> 0.088519075 | G11: =G10/G8 -> 0.10761455 | H11: =H10/H8 -> 0.082315807 | I11: =I10/I8 -> 0.055986356
C12: *Compound Annual Growth Rate
C13: # Earnings Before Interest, Taxes, Depreciation and Amortization
D14: FY09 | E14: 2009 | F14: 2010 | G14: 2011 | H14: 2012 | I14: 2013
C15: Revenue | D15: =[4]Revenue!D10/1000 -> 262.52703 | E15: =ROUND(E8/1000, 0) -> 95 | F15: =ROUND(F8/1000, 0) -> 100 | G15: =ROUND(G8/1000, 0) -> 105 | H15: =ROUND(H8/1000, 0) -> 105 | I15: =ROUND(I8/1000, 0) -> 105
C16: Expenses | D16: =[4]Revenue!D6/1000 -> 25.42175 | E16: =ROUND(E9/1000, 0) -> 89 | F16: =ROUND(F9/1000, 0) -> 91 | G16: =ROUND(G9/1000, 0) -> 94 | H16: =ROUND(H9/1000, 0) -> 96 | I16: =ROUND(I9/1000, 0) -> 99
C17: =C11 -> Profit Margin | D17: =D15-D16 -> 237.10528 | E17: =E15-E16 -> 6 | F17: =F15-F16 -> 9 | G17: =G15-G16 -> 11 | H17: =H15-H16 -> 9 | I17: =I15-I16 -> 6

Sheet Expense Analysis
A1: File | B1: ='Table of Contents'!B1 -> Electronics Manufacturing Venture | E1: Red | F1: Requires further attention
A2: Author | B2: ='Table of Contents'!B2 -> Krishnamurthy Bindumadhavan | E2: Blue | F2: Input cells
A3: Tab | B3: Expense Analysis | E3: Green | F3: Cells linked to another sheet
A4: Created | B4: 46033 | E4: Black | F4: Cells containing a calculation on the same sheet
L5: originally entered from 990
L6: 990 - FY10 | M6: 990 - FY11 | N6: 990 - FY12
C7: Expenses | D7: 2015 | E7: 2016 | F7: 2017 | G7: 2018 | H7: 2019 | I7: CAGR * | L7: 62750 | M7: =T7/1000 -> 0 | N7: =U7/1000 -> 0
C8: Salaries and Wages | D8: =SUM('[3]Income Statement'!$C92:$N93) -> 41250.812 | E8: =SUM('[3]Income Statement'!$O92:$Z93) -> 42931.434 | F8: =SUM('[3]Income Statement'!$AA92:$AL93) -> 44680.527 | G8: =SUM('[3]Income Statement'!$AM92:$AX93) -> 46500.88 | H8: =SUM('[3]Income Statement'!$AY92:$BJ93) -> 48395.398 | I8: =+(H8/D8)^(1/4)-1 -> 0.040741543 | J8: =H8/E8 - 1 -> 0.12727187 | L8: =54000+5482+9926 -> 69408 | M8: =104626+16595+5615+10588 -> 137424 | N8: =60751+ 48908 +8919.55 -> 118578.55
C9: Professional Services | D9: =SUM('[3]Income Statement'!$C77:$N77) -> 1000 | E9: =SUM('[3]Income Statement'!$O77:$Z77) -> 1000 | F9: =SUM('[3]Income Statement'!$AA77:$AL77) -> 1000 | G9: =SUM('[3]Income Statement'!$AM77:$AX77) -> 1000 | H9: =SUM('[3]Income Statement'!$AY77:$BJ77) -> 1000 | I9: =+(H9/D9)^(1/4)-1 -> 0 | J9: =H9/E9 - 1 -> 0 | L9: 0 | M9: 26038 | N9: =U9/1000 -> 0
C10: Other Cash Expenses | D10: =SUM('[3]Income Statement'!$C68:$N68) -> 17000 | E10: =SUM('[3]Income Statement'!$O68:$Z68) -> 17000 | F10: =SUM('[3]Income Statement'!$AA68:$AL68) -> 17000 | G10: =SUM('[3]Income Statement'!$AM68:$AX68) -> 17000 | H10: =SUM('[3]Income Statement'!$AY68:$BJ68) -> 17000 | I10: =+(H10/D10)^(1/4)-1 -> 0 | J10: =H10/E10 - 1 -> 0
C11: Travel | D11: =SUM('[3]Income Statement'!$C69:$N69) -> 9000 | E11: =SUM('[3]Income Statement'!$O69:$Z69) -> 9000 | F11: =SUM('[3]Income Statement'!$AA69:$AL69) -> 9000 | G11: =SUM('[3]Income Statement'!$AM69:$AX69) -> 9000 | H11: =SUM('[3]Income Statement'!$AY69:$BJ69) -> 9000 | I11: =+(H11/D11)^(1/4)-1 -> 0 | J11: =H11/E11 - 1 -> 0
C12: Other Direct Costs | D12: =SUM('[3]Income Statement'!$C84:$N84) -> 600 | E12: =SUM('[3]Income Statement'!$O84:$Z84) -> 600 | F12: =SUM('[3]Income Statement'!$AA84:$AL84) -> 600 | G12: =SUM('[3]Income Statement'!$AM84:$AX84) -> 600 | H12: =SUM('[3]Income Statement'!$AY84:$BJ84) -> 600 | I12: =+(H12/D12)^(1/4)-1 -> 0 | J12: =H12/E12 - 1 -> 0 | L12: 0 | M12: =T12/1000 -> 0 | N12: =U12/1000 -> 0
C13: Miscellaneous | D13: =SUM('[3]Income Statement'!$C94:$N105) + SUM('[3]Income Statement'!$C113:$N113) -> 19844.817 | E13: =SUM('[3]Income Statement'!$O94:$Z105) + SUM('[3]Income Statement'!$O113:$Z113) -> 20616.659 | F13: =SUM('[3]Income Statement'!$AA94:$AL105) + SUM('[3]Income Statement'!$AA113:$AL113) -> 21419.946 | G13: =SUM('[3]Income Statement'!$AM94:$AX105)+SUM('[3]Income Statement'!$AM113:$AX113) -> 22255.96 | H13: =SUM('[3]Income Statement'!$AY94:$BJ105) + SUM('[3]Income Statement'!$AY113:$BJ113) -> 23126.035 | I13: =+(H13/D13)^(1/4)-1 -> 0.038995139 | J13: =H13/E13 - 1 -> 0.12171595
C14: Total Expenses | D14: =SUM(D8:D13) -> 88695.63 | E14: =SUM(E8:E13) -> 91148.092 | F14: =SUM(F8:F13) -> 93700.472 | G14: =SUM(G8:G13) -> 96356.84 | H14: =SUM(H8:H13) -> 99121.433 | I14: =+(H14/D14)^(1/4)-1 -> 0.028173337 | J14: =H14/E14 - 1 -> 0.087476764 | L14: 7000 | M14: =T14/1000 -> 0 | N14: =U14/1000 -> 0
C15: *Compound Annual Growth Rate | K15: =H14/E14 -> 1.0874768 | L15: =400+5428 -> 5828 | M15: =T15/1000 -> 0 | N15: =12267 -> 12267
H16: =H14/D14 - 1 -> 0.11754585 | J16: =SUM(H9:H13)/SUM(E9:E13) -> 1.0520438 | L16: 0 | M16: 73993 | N16: 23321
C17: Common Size Analysis | L17: 0 | M17: 15205 | N17: 16626
C18: =C7 -> Expenses | D18: =D7 -> 2015 | E18: =E7 -> 2016 | F18: =F7 -> 2017 | G18: =G7 -> 2018 | H18: =H7 -> 2019 | J18: =H8/E8 -> 1.1272719 | L18: 5197 | M18: 9358 | N18: 2279
C19: =C8 -> Salaries and Wages | D19: =D8/D$14 -> 0.4650828 | E19: =E8/E$14 -> 0.47100749 | F19: =F8/F$14 -> 0.4768442 | G19: =G8/G$14 -> 0.48259034 | H19: =H8/H$14 -> 0.48824353 | N19: 477
C20: =C9 -> Professional Services | D20: =D9/D$14 -> 0.011274513 | E20: =E9/E$14 -> 0.010971157 | F20: =F9/F$14 -> 0.010672305 | G20: =G9/G$14 -> 0.01037809 | H20: =H9/H$14 -> 0.010088635 | L20: =110+5142+11874 -> 17126 | N20: 4144
C21: =C10 -> Other Cash Expenses | D21: =D10/D$14 -> 0.19166672 | E21: =E10/E$14 -> 0.18650966 | F21: =F10/F$14 -> 0.18142918 | G21: =G10/G$14 -> 0.17642754 | H21: =H10/H$14 -> 0.1715068
C22: =C11 -> Travel | D22: =D11/D$14 -> 0.10147061 | E22: =E11/E$14 -> 0.09874041 | F22: =F11/F$14 -> 0.096050743 | G22: =G11/G$14 -> 0.093402814 | H22: =H11/H$14 -> 0.090797719
C23: =C12 -> Other Direct Costs | D23: =D12/D$14 -> 0.0067647076 | E23: =E12/E$14 -> 0.006582694 | F23: =F12/F$14 -> 0.0064033829 | G23: =G12/G$14 -> 0.0062268542 | H23: =H12/H$14 -> 0.0060531813 | L23: 74060 | M23: 51912 | N23: 41573
C24: =C13 -> Miscellaneous | D24: =D13/D$14 -> 0.22374065 | E24: =E13/E$14 -> 0.22618859 | F24: =F13/F$14 -> 0.22860019 | G24: =G13/G$14 -> 0.23097436 | H24: =H13/H$14 -> 0.23331013
C25: =C14 -> Total Expenses | D25: =D14/D$14 -> 1 | E25: =E14/E$14 -> 1 | F25: =F14/F$14 -> 1 | G25: =G14/G$14 -> 1 | H25: =H14/H$14 -> 1
C28: Pie Chart | D28: =H7 -> 2019
C29: =C8 -> Salaries and Wages | D29: =H8 -> 48395.398 | L29: =2572+336+53+63 -> 3024 | M29: =74+180+63 -> 317 | N29: =58+785 -> 843
C30: =C9 -> Professional Services | D30: =H9 -> 1000 | L30: 0 | M30: =T30/1000 -> 0 | N30: 275915
C31: =C10 -> Other Cash Expenses | D31: =H10 -> 17000
C32: =C11 -> Travel | D32: =H11 -> 9000
C33: =C12 -> Other Direct Costs | D33: =H12 -> 600 | L33: =SUM(L7:L30) -> 244393 | M33: =SUM(M7:M30) -> 314247 | N33: =SUM(N7:N30) -> 496023.55 | P33: =M33-M9 -> 288209
C34: =C13 -> Miscellaneous | D34: =H13 -> 23126.035
C35: =C14 -> Total Expenses | D35: =H14 -> 99121.433

Sheet Revenue Analysis
A1: File | B1: ='Table of Contents'!B1 -> Electronics Manufacturing Venture | E1: Red | F1: Requires further attention
A2: Author | B2: ='Table of Contents'!B2 -> Krishnamurthy Bindumadhavan | E2: Blue | F2: Input cells
A3: Tab | B3: Revenue Analysis | E3: Green | F3: Cells linked to another sheet
A4: Created | B4: 46033 | E4: Black | F4: Cells containing a calculation on the same sheet
C7: Revenues | D7: 2015 | E7: 2016 | F7: 2017 | G7: 2018 | H7: 2019 | I7: CAGR *
C8: Medical Exams | D8: =SUM('[3]Income Statement'!$C17:$N17) -> 73000 | E8: =SUM('[3]Income Statement'!$O17:$Z17) -> 78000 | F8: =SUM('[3]Income Statement'!$AA17:$AL17) -> 83000 | G8: =SUM('[3]Income Statement'!$AM17:$AX17) -> 83000 | H8: =SUM('[3]Income Statement'!$AY17:$BJ17) -> 83000 | I8: =+(H8/D8)^(1/4)-1 -> 0.0326159
C9: Product Sales | D9: =SUM('[3]Income Statement'!$C23:$N23) -> 8000 | E9: =SUM('[3]Income Statement'!$O23:$Z23) -> 8000 | F9: =SUM('[3]Income Statement'!$AA23:$AL23) -> 8000 | G9: =SUM('[3]Income Statement'!$AM23:$AX23) -> 8000 | H9: =SUM('[3]Income Statement'!$AY23:$BJ23) -> 8000 | I9: =+(H9/D9)^(1/4)-1 -> 0
C10: Misc 1 | D10: =SUM('[3]Income Statement'!$C29:$N29) -> 5000 | E10: =SUM('[3]Income Statement'!$O29:$Z29) -> 5000 | F10: =SUM('[3]Income Statement'!$AA29:$AL29) -> 5000 | G10: =SUM('[3]Income Statement'!$AM29:$AX29) -> 5000 | H10: =SUM('[3]Income Statement'!$AY29:$BJ29) -> 5000 | I10: =+(H10/D10)^(1/4)-1 -> 0
C11: Misc 2 | D11: =SUM('[3]Income Statement'!$C35:$N35) -> 9000 | E11: =SUM('[3]Income Statement'!$O35:$Z35) -> 9000 | F11: =SUM('[3]Income Statement'!$AA35:$AL35) -> 9000 | G11: =SUM('[3]Income Statement'!$AM35:$AX35) -> 9000 | H11: =SUM('[3]Income Statement'!$AY35:$BJ35) -> 9000 | I11: =+(H11/D11)^(1/4)-1 -> 0
C12: ='[3]Income Statement'!B37 -> Other Revenue | D12: =SUM('[3]Income Statement'!$C40:$N40) -> 0 | E12: =SUM('[3]Income Statement'!$O40:$Z40) -> 0 | F12: =SUM('[3]Income Statement'!$AA40:$AL40) -> 0 | G12: =SUM('[3]Income Statement'!$AM40:$AX40) -> 0 | H12: =SUM('[3]Income Statement'!$AY40:$BJ40) -> 0 | I12: 1
C13: Total Revenue | D13: =SUM(D8:D12) -> 95000 | E13: =SUM(E8:E12) -> 100000 | F13: =SUM(F8:F12) -> 105000 | G13: =SUM(G8:G12) -> 105000 | H13: =SUM(H8:H12) -> 105000 | I13: =+(H13/D13)^(1/4)-1 -> 0.025336514
C14: *Compound Annual Growth Rate
D15: 2015 | E15: 2016 | F15: 2017 | G15: 2018 | H15: 2019
C16: Total Revenue | D16: =D13/1000 -> 95 | E16: =E13/1000 -> 100 | F16: =F13/1000 -> 105 | G16: =G13/1000 -> 105 | H16: =H13/1000 -> 105
D18: Break down of revenue
D20: =C8 -> Medical Exams | E20: =H8 -> 83000
D21: =C9 -> Product Sales | E21: =H9 -> 8000
D22: =C10 -> Misc 1 | E22: =H10 -> 5000
D23: =C11 -> Misc 2 | E23: =H11 -> 9000
D24: =C12 -> Other Revenue | E24: =H12 -> 0
D25: Total | E25: =SUM(E20:E24) -> 105000

Sheet Cashflow Analysis
A1: File | B1: ='Table of Contents'!B1 -> Electronics Manufacturing Venture | E1: Red | F1: Requires further attention
A2: Author | B2: ='Table of Contents'!B2 -> Krishnamurthy Bindumadhavan | E2: Blue | F2: Input cells
A3: Tab | B3: Cashflow Analysis | E3: Green | F3: Cells linked to another sheet
A4: Created | B4: 46033 | E4: Black | F4: Cells containing a calculation on the same sheet
C6: Statement of Cashflows | D6: 2015 | E6: 2016 | F6: 2017 | G6: 2018 | H6: 2019
C7: Beginning Cash | D7: 0 | E7: =D13 -> 2704.3703 | F7: =E13 -> 12456.278 | G7: =F13 -> 24655.805 | H7: =G13 -> 34198.965
C8: Net Income (Loss) | D8: =[3]Dashboard!C12 -> 6304.3703 | E8: =[3]Dashboard!D12 -> 8851.9075 | F8: =[3]Dashboard!E12 -> 11299.528 | G8: =[3]Dashboard!F12 -> 8643.1597 | H8: =[3]Dashboard!G12 -> 5878.5673
C9: Depreciation | D9: =[3]Dashboard!C10-[3]Dashboard!C11 -> 900 | E9: =[3]Dashboard!D10-[3]Dashboard!D11 -> 900 | F9: =[3]Dashboard!E10-[3]Dashboard!E11 -> 900 | G9: =[3]Dashboard!F10-[3]Dashboard!F11 -> 900 | H9: =[3]Dashboard!G10-[3]Dashboard!G11 -> 900
C10: (Incr) Decr Current Assets | D10: =-(D17-C17) -> -2704.3703 | E10: =-(E17-D17) -> -9751.9075 | F10: =-(F17-E17) -> -12199.528 | G10: =-(G17-F17) -> -9543.1597 | H10: =-(H17-G17) -> -6778.5673
C11: Incr (Decr) Current Liabilities | D11: =D18-C18 -> 0 | E11: =E18-D18 -> 0 | F11: =F18-E18 -> 0 | G11: =G18-F18 -> 0 | H11: =H18-G18 -> 0
C12: Other (net) | D12: =D13-SUM(D7:D11) -> -1795.6297 | E12: =E13-SUM(E7:E11) -> 9751.9075 | F12: =F13-SUM(F7:F11) -> 12199.528 | G12: =G13-SUM(G7:G11) -> 9543.1597 | H12: =H13-SUM(H7:H11) -> 6778.5673
C13: Ending Cash | D13: =[3]Dashboard!C34 -> 2704.3703 | E13: =[3]Dashboard!D34 -> 12456.278 | F13: =[3]Dashboard!E34 -> 24655.805 | G13: =[3]Dashboard!F34 -> 34198.965 | H13: =[3]Dashboard!G34 -> 40977.532
C14: Incr (Decr) in Cash | D14: =D13-D7 -> 2704.3703 | E14: =E13-E7 -> 9751.9075 | F14: =F13-F7 -> 12199.528 | G14: =G13-G7 -> 9543.1597 | H14: =H13-H7 -> 6778.5673
C16: =C21 -> 2014 | D16: =D21 -> 2015 | E16: =E21 -> 2016 | F16: =F21 -> 2017 | G16: =G21 -> 2018 | H16: =H21 -> 2019
B17: Current Assets | C17: 0 | D17: =[3]Dashboard!C18 -> 2704.3703 | E17: =[3]Dashboard!D18 -> 12456.278 | F17: =[3]Dashboard!E18 -> 24655.805 | G17: =[3]Dashboard!F18 -> 34198.965 | H17: =[3]Dashboard!G18 -> 40977.532
B18: Current Liabilities | C18: 0 | D18: 0 | E18: 0 | F18: 0 | G18: 0 | H18: ='[5]BS 2013'!B32 -> 0
C20: Year End Cash Balances
C21: 2014 | D21: =D6 -> 2015 | E21: =E6 -> 2016 | F21: =F6 -> 2017 | G21: =G6 -> 2018 | H21: =H6 -> 2019
C22: =D7 -> 0 | D22: =D13 -> 2704.3703 | E22: =E13 -> 12456.278 | F22: =F13 -> 24655.805 | G22: =G13 -> 34198.965 | H22: =H13 -> 40977.532
C24: January 1 - Dec 31 2013
E25: End Points | F25: Before | G25: After
C26: Beginning Cash | D26: =H7 -> 34198.965 | E26: =D26 -> 34198.965
C27: Net Income (Loss) | D27: =H8 -> 5878.5673 | F27: =SUM(D$26:D26) -> 34198.965 | G27: =SUM(D$26:D27) -> 40077.532
C28: Depreciation | D28: =H9 -> 900 | F28: =SUM(D$26:D27) -> 40077.532 | G28: =SUM(D$26:D28) -> 40977.532
C29: (Incr) Decr Current Assets | D29: =H10 -> -6778.5673 | F29: =SUM(D$26:D28) -> 40977.532 | G29: =SUM(D$26:D29) -> 34198.965
C30: Incr (Decr) Current Liabilities | D30: =H11 -> 0 | F30: =SUM(D$26:D29) -> 34198.965 | G30: =SUM(D$26:D30) -> 34198.965
C31: Other (net) | D31: =H12 -> 6778.5673 | F31: =SUM(D$26:D30) -> 34198.965 | G31: =SUM(D$26:D31) -> 40977.532
C32: Ending Cash | E32: =SUM(D26:D31) -> 40977.532

Sheet Loan Repayment Schedule
A1: File | B1: ='Table of Contents'!B1 -> Electronics Manufacturing Venture | F1: Red | G1: Requires further attention
A2: Author | B2: ='Table of Contents'!B2 -> Krishnamurthy Bindumadhavan | F2: Blue | G2: Input cells
A3: Tab | B3: Loan Repayment Schedule | F3: Green | G3: Cells linked to another sheet
A4: Created | B4: 46033 | F4: Black | G4: Cells containing a calculation on the same sheet
C6: Interest Rate | D6: =Assumptions!D14 -> 0.15 | H6: Fixed Assets + Inventory | J6: ='Depreciation Schedule'!F23+SUM(Assumptions!J45:J48) -> 587111.11
C7: Loan Term | D7: =Assumptions!D15 -> 10 | G7: Years
C8: EMI | D8: =-PMT(D6/12, D7*12, H13, 0) -> 8665.4798
C11: Loan Repayment Schedule - Monthly | H11: Projected Financials
H12: 1 | I12: 2 | J12: 3 | K12: 4 | L12: 5 | M12: 6 | N12: 7 | O12: 8 | P12: 9 | Q12: 10 | R12: 11 | S12: 12 | T12: 13 | U12: 14 | V12: 15 | W12: 16 | X12: 17 | Y12: 18 | Z12: 19 | AA12: 20 | AB12: 21 | AC12: 22 | AD12: 23 | AE12: 24 | AF12: 25 | AG12: 26 | AH12: 27 | AI12: 28 | AJ12: 29 | AK12: 30 | AL12: 31 | AM12: 32 | AN12: 33 | AO12: 34 | AP12: 35 | AQ12: 36 | AR12: 37 | AS12: 38 | AT12: 39 | AU12: 40 | AV12: 41 | AW12: 42 | AX12: 43 | AY12: 44 | AZ12: 45 | BA12: 46 | BB12: 47 | BC12: 48 | BD12: 49 | BE12: 50 | BF12: 51 | BG12: 52 | BH12: 53 | BI12: 54 | BJ12: 55 | BK12: 56 | BL12: 57 | BM12: 58 | BN12: 59 | BO12: 60 | BP12: 61 | BQ12: 62 | BR12: 63 | BS12: 64 | BT12: 65 | BU12: 66 | BV12: 67 | BW12: 68 | BX12: 69 | BY12: 70 | BZ12: 71 | CA12: 72 | CB12: 73 | CC12: 74 | CD12: 75 | CE12: 76 | CF12: 77 | CG12: 78 | CH12: 79 | CI12: 80 | CJ12: 81 | CK12: 82 | CL12: 83 | CM12: 84 | CN12: 85 | CO12: 86 | CP12: 87 | CQ12: 88 | CR12: 89 | CS12: 90 | CT12: 91 | CU12: 92 | CV12: 93 | CW12: 94 | CX12: 95 | CY12: 96 | CZ12: 97 | DA12: 98 | DB12: 99 | DC12: 100 | DD12: 101 | DE12: 102 | DF12: 103 | DG12: 104 | DH12: 105 | DI12: 106 | DJ12: 107 | DK12: 108 | DL12: 109 | DM12: 110 | DN12: 111 | DO12: 112 | DP12: 113 | DQ12: 114 | DR12: 115 | DS12: 116 | DT12: 117 | DU12: 118 | DV12: 119 | DW12: 120
C13: Beginning Loan Balance | H13: ='Loan Repayment Schedule'!J6-'Balance Sheet'!H35 -> 537111.11 | I13: =H17 -> 535159.52 | J13: =I17 -> 533183.53 | K13: =J17 -> 531182.85 | L13: =K17 -> 529157.15 | M13: =L17 -> 527106.14 | N13: =M17 -> 525029.49 | O13: =N17 -> 522926.87 | P13: =O17 -> 520797.98 | ... DW13: =DV17 -> 8558.4986
C14: EMI | H14: =D8 -> 8665.4798 | I14: =H14 -> 8665.4798 | J14: =I14 -> 8665.4798 | K14: =J14 -> 8665.4798 | L14: =K14 -> 8665.4798 | M14: =L14 -> 8665.4798 | N14: =M14 -> 8665.4798 | O14: =N14 -> 8665.4798 | P14: =O14 -> 8665.4798 | ... DW14: =DV14 -> 8665.4798
C15: Interest Payment | H15: =H13*$D$6/12 -> 6713.8889 | I15: =I13*$D$6/12 -> 6689.494 | J15: =J13*$D$6/12 -> 6664.7942 | K15: =K13*$D$6/12 -> 6639.7856 | L15: =L13*$D$6/12 -> 6614.4644 | M15: =M13*$D$6/12 -> 6588.8267 | N15: =N13*$D$6/12 -> 6562.8686 | O15: =O13*$D$6/12 -> 6536.5859 | ... DW15: =DW13*$D$6/12 -> 106.98123
C16: Principal Payment | H16: =H14-H15 -> 1951.5909 | I16: =I14-I15 -> 1975.9858 | J16: =J14-J15 -> 2000.6856 | K16: =K14-K15 -> 2025.6942 | L16: =L14-L15 -> 2051.0154 | M16: =M14-M15 -> 2076.6531 | N16: =N14-N15 -> 2102.6112 | O16: =O14-O15 -> 2128.8939 | ... DW16: =DW14-DW15 -> 8558.4986
C17: Ending Loan Balance | H17: =H13-H16 -> 535159.52 | I17: =I13-I16 -> 533183.53 | J17: =J13-J16 -> 531182.85 | K17: =K13-K16 -> 529157.15 | L17: =L13-L16 -> 527106.14 | M17: =M13-M16 -> 525029.49 | N17: =N13-N16 -> 522926.87 | O17: =O13-O16 -> 520797.98 | ... DW17: =DW13-DW16 -> -1.1314114e-09
C20: Loan Repayment Schedule - Annual | H20: Projected Financials
H21: Year 1 | I21: Year 2 | J21: Year 3 | K21: Year 4 | L21: Year 5 | M21: Year 6 | N21: Year 7 | O21: Year 8 | P21: Year 9 | Q21: Year 10
C22: Beginning Loan Balance | H22: =H13 -> 537111.11 | I22: =H26 -> 512012.95 | J22: =I26 -> 482880.14 | K22: =J26 -> 449064.1 | L22: =K26 -> 409811.98 | M22: =L26 -> 364249.91 | N22: =M26 -> 311363.52 | O22: =N26 -> 249975.41 | P22: =O26 -> 178718.89 | Q22: =P26 -> 96007.554
C23: EMI | H23: =SUM(H14:S14) -> 103985.76 | I23: =H23 -> 103985.76 | J23: =I23 -> 103985.76 | K23: =J23 -> 103985.76 | L23: =K23 -> 103985.76 | M23: =L23 -> 103985.76 | N23: =M23 -> 103985.76 | O23: =N23 -> 103985.76 | P23: =O23 -> 103985.76 | Q23: =P23 -> 103985.76
C24: Interest Payment | H24: =SUM(H15:S15) -> 78887.593 | I24: =SUM(T15:AE15) -> 74852.95 | J24: =SUM(AF15:AQ15) -> 70169.719 | K24: =SUM(AR15:BC15) -> 64733.638 | L24: =SUM(BD15:BO15) -> 58423.683 | M24: =SUM(BP15:CA15) -> 51099.374 | N24: =SUM(CB15:CM15) -> 42597.648 | O24: =SUM(CN15:CY15) -> 32729.232 | P24: =SUM(CZ15:DK15) -> 21274.424 | Q24: =SUM(DL15:DW15) -> 7978.2036
C25: Principal Payment | H25: =SUM(H16:S16) -> 25098.165 | I25: =SUM(T16:AE16) -> 29132.808 | J25: =SUM(AF16:AQ16) -> 33816.038 | K25: =SUM(AR16:BC16) -> 39252.119 | L25: =SUM(BD16:BO16) -> 45562.075 | M25: =SUM(BP16:CA16) -> 52886.384 | N25: =SUM(CB16:CM16) -> 61388.109 | O25: =SUM(CN16:CY16) -> 71256.525 | P25: =SUM(CZ16:DK16) -> 82711.334 | Q25: =SUM(DL16:DW16) -> 96007.554
C26: Ending Loan Balance | H26: =H22-H25 -> 512012.95 | I26: =I22-I25 -> 482880.14 | J26: =J22-J25 -> 449064.1 | K26: =K22-K25 -> 409811.98 | L26: =L22-L25 -> 364249.91 | M26: =M22-M25 -> 311363.52 | N26: =N22-N25 -> 249975.41 | O26: =O22-O25 -> 178718.89 | ... Q26: =Q22-Q25 -> -8.7311491e-10
C29: Net Debt | G29: Year 0 | H29: Year 1 | I29: Year 2 | J29: Year 3 | K29: Year 4 | L29: Year 5 | M29: Year 6 | N29: Year 7 | O29: Year 8 | P29: Year 9 | Q29: Year 10
C30: New Debt Issued | G30: =H13 -> 537111.11 | H30: =G34 -> 537111.11 | I30: =H34 -> 512012.95 | J30: =I34 -> 482880.14 | K30: =J34 -> 449064.1 | L30: =K34 -> 409811.98 | M30: =L34 -> 364249.91 | N30: =M34 -> 311363.52 | O30: =N34 -> 249975.41 | ... Q30: =P34 -> 96007.554
C31: Existing Debt Interest payments | G31: 0 | H31: =H24 -> 78887.593 | I31: =I24 -> 74852.95 | J31: =J24 -> 70169.719 | K31: =K24 -> 64733.638 | L31: =L24 -> 58423.683 | M31: =M24 -> 51099.374 | N31: =N24 -> 42597.648 | O31: =O24 -> 32729.232 | ... Q31: =Q24 -> 7978.2036
C32: Existing Debt Principal payments | G32: 0 | H32: =H25 -> 25098.165 | I32: =I25 -> 29132.808 | J32: =J25 -> 33816.038 | K32: =K25 -> 39252.119 | L32: =L25 -> 45562.075 | M32: =M25 -> 52886.384 | N32: =N25 -> 61388.109 | O32: =O25 -> 71256.525 | ... Q32: =Q25 -> 96007.554
C33: Interest x (1 - Tax Rate) | G33: =G31*(1-[1]Assumptions!$D$12) -> 0 | H33: =H31*(1-Assumptions!$D$12) -> 51276.936 | I33: =I31*(1-Assumptions!$D$12) -> 48654.417 | J33: =J31*(1-Assumptions!$D$12) -> 45610.318 | K33: =K31*(1-Assumptions!$D$12) -> 42076.865 | L33: =L31*(1-Assumptions!$D$12) -> 37975.394 | M33: =M31*(1-Assumptions!$D$12) -> 33214.593 | N33: =N31*(1-Assumptions!$D$12) -> 27688.471 | O33: =O31*(1-Assumptions!$D$12) -> 21274.001 | ... Q33: =Q31*(1-Assumptions!$D$12) -> 5185.8323
C34: Net Debt | G34: =G30-G32-G33 -> 537111.11 | H34: =H30-H32 -> 512012.95 | I34: =I30-I32 -> 482880.14 | J34: =J30-J32 -> 449064.1 | K34: =K30-K32 -> 409811.98 | L34: =L30-L32 -> 364249.91 | M34: =M30-M32 -> 311363.52 | N34: =N30-N32 -> 249975.41 | O34: =O30-O32 -> 178718.89 | ... Q34: =Q30-Q32 -> -8.7311491e-10
C36: Note difference between Yr0 and Yr1

Sheet Depreciation Schedule
A1: File | B1: ='Table of Contents'!B1 -> Electronics Manufacturing Venture | F1: Red | G1: Requires further attention
A2: Author | B2: ='Table of Contents'!B2 -> Krishnamurthy Bindumadhavan | F2: Blue | G2: Input cells
A3: Tab | B3: Depreciation Schedule | F3: Green | G3: Cells linked to another sheet
A4: Created | B4: 46033 | F4: Black | G4: Cells containing a calculation on the same sheet
C7: Depreciation | G7: Projected Financials
G8: Year 1 | H8: Year 2 | I8: Year 3 | J8: Year 4 | K8: Year 5 | L8: Year 6 | M8: Year 7 | N8: Year 8 | O8: Year 9 | P8: Year 10
C9: Total Beginning Value | G9: ='Depreciation Schedule'!F23 -> 206111.11 | H9: =G12 -> 185500 | I9: =H12 -> 164888.89 | J9: =I12 -> 144277.78 | K9: =J12 -> 123666.67 | L9: =K12 -> 103055.56 | M9: =L12 -> 82444.444 | N9: =M12 -> 61833.333 | O9: =N12 -> 41222.222 | P9: =O12 -> 20611.111
C10: Total Depreciation Expense | G10: ='Depreciation Schedule'!F23/$F$24 -> 20611.111 | H10: =G10 -> 20611.111 | I10: =H10 -> 20611.111 | J10: =I10 -> 20611.111 | K10: =J10 -> 20611.111 | L10: =K10 -> 20611.111 | M10: =L10 -> 20611.111 | N10: =M10 -> 20611.111 | O10: =N10 -> 20611.111 | P10: =O10 -> 20611.111
C11: Accumlated Depreciation | G11: =F11+G10 -> 20611.111 | H11: =G11+H10 -> 41222.222 | I11: =H11+I10 -> 61833.333 | J11: =I11+J10 -> 82444.444 | K11: =J11+K10 -> 103055.56 | L11: =K11+L10 -> 123666.67 | M11: =L11+M10 -> 144277.78 | N11: =M11+N10 -> 164888.89 | ... P11: =O11+P10 -> 206111.11
C12: Total Ending Balance | G12: =G9-G10 -> 185500 | H12: =H9-H10 -> 164888.89 | I12: =I9-I10 -> 144277.78 | J12: =J9-J10 -> 123666.67 | K12: =K9-K10 -> 103055.56 | L12: =L9-L10 -> 82444.444 | M12: =M9-M10 -> 61833.333 | N12: =N9-N10 -> 41222.222 | ... P12: =P9-P10 -> 0
C16: Details of depreciable items: | F16: Amount | I16: Machinery | J16: Rupees
C17: Machinery | F17: =J29 -> 116111.11 | H17: 1) | I17: Pick and Place | J17: 2000000
C18: Factory Preparation, False Ceiling, Power backup, Airconditioning, Electronics Assembly line, Workbench, Furniture, Installation, etc. | F18: =Assumptions!D20 -> 75000 | H18: 2) | I18: Wave Soldering | J18: 1000000
C19: Security system | F19: =Assumptions!D21 -> 5000 | H19: 3) | I19: Moulding Machine | J19: 2000000
C20: IT installation | F20: =Assumptions!D22 -> 5000 | H20: 4) | I20: 3D Printer | J20: =5000*90 -> 450000
C21: Miscellaneous | F21: =Assumptions!D23 -> 5000 | H21: 5) | I21: SMT Stencil Printer | J21: 1000000
H22: 6) | I22: Quality Inspection machines | J22: 2000000
C23: Total depreciable items | F23: =SUM(F17:F21) -> 206111.11 | H23: 7) | I23: Miscellaneous equipment | J23: 2000000
C24: Depreciable life | F24: =[1]Assumptions!D16 -> 10 | G24: Years
I25: Total | J25: =SUM(J17:J23) -> 10450000
F26: =F23*J27 -> 18550000
I27: INR/ USD | J27: 90
I29: USD Cost | J29: =J25/J27 -> 116111.11

Sheet Dashboard
A1: File | B1: ='Table of Contents'!B1 -> Electronics Manufacturing Venture | F1: Red | G1: Requires further attention
A2: Author | B2: ='Table of Contents'!B2 -> Krishnamurthy Bindumadhavan | F2: Blue | G2: Input cells
A3: Tab | B3: Dashboard | F3: Green | G3: Cells linked to another sheet
A4: Created | B4: 46033 | F4: Black | G4: Cells containing a calculation on the same sheet
A7: Revenue Break-down | C7: ='[1]Income Statement'!C6 -> Year 1 | D7: Proportion
A8: Medical Exams | C8: ='[1]Income Statement'!C70 -> 585984 | D8: =C8/$C$10 -> 0.4722996
A9: Product Sales | C9: ='[1]Income Statement'!C139 -> 654720 | D9: =C9/$C$10 -> 0.5277004
A10: Total | C10: =SUM(C8:C9) -> 1240704
A12: Expenses Break-down | C12: =C7 -> Year 1 | D12: =D7 -> Proportion | F12: w/o start-up
A13: ='[1]Income Statement'!A147 -> Cost of Good Sold | C13: ='[1]Income Statement'!C158 -> 238272 | D13: =C13/$C$17 -> 0.43931471 | E13: =A13 -> Cost of Good Sold | F13: =C13/($C$17-$C$14) -> 0.46961992
A14: ='[1]Income Statement'!A164 -> Startup Costs | C14: ='[1]Income Statement'!C174 -> 35000 | D14: =C14/$C$17 -> 0.064531355 | E14: =A15 -> Operating Costs | F14: =C15/($C$17-$C$14) -> 0.5195399
A15: ='[1]Income Statement'!A176 -> Operating Costs | C15: ='[1]Income Statement'!C193 -> 263600 | D15: =C15/$C$17 -> 0.48601329 | E15: Annual Expenses | F15: =C16/($C$17-$C$14) -> 0.010840172
